--------------------
2017-11-14 07:58:26 - Exception on message: {'id': '02z2ux2xtj4sg', 'time': 1510646306, 'sender': {'id': 'account:01ha19ib9296o', 'name': 'Pouncy Silverkitten', 'server_id': 'heim.2', 'server_era': '02xttnydj5xj4', 'session_id': '746564632d686e72744d593d-ef34bec079d20b1d'}, 'content': '!roomstats', 'edited': None, 'deleted': None, 'parent': ''}:
Traceback (most recent call last):
  File "heimdall.py", line 319, in <module>
    perDayLastFourWeeks = int(last28Days[0]/28)
TypeError: unsupported operand type(s) for /: 'tuple' and 'int'


--------------------
2017-11-14 07:59:55 - Exception on message: {'id': '02z2v1ti8xczk', 'parent': '02z2ux2xtj4sg', 'time': 1510646395, 'sender': {'id': 'account:01ha19ib9296o', 'name': 'Pouncy Silverkitten', 'server_id': 'heim.2', 'server_era': '02xttnydj5xj4', 'session_id': '746564632d686e72744d593d-ef34bec079d20b1d'}, 'content': '!roomstats', 'edited': None, 'deleted': None}:
Traceback (most recent call last):
  File "heimdall.py", line 319, in <module>
    perDayLastFourWeeks = int(last28Days[0]/28)
TypeError: unsupported operand type(s) for /: 'tuple' and 'int'


--------------------
2017-11-14 08:02:59 - Exception on message: {'id': '02z2vbnj5upz4', 'parent': '02z2ux2xtj4sg', 'time': 1510646578, 'sender': {'id': 'account:01ha19ib9296o', 'name': 'Pouncy Silverkitten', 'server_id': 'heim.2', 'server_era': '02xttnydj5xj4', 'session_id': '746564632d686e72744d593d-ef34bec079d20b1d'}, 'content': '!roomstats', 'edited': None, 'deleted': None}:
Traceback (most recent call last):
  File "heimdall.py", line 316, in <module>
    print(lowerBound.utcfromtimestamp(0))
AttributeError: 'float' object has no attribute 'utcfromtimestamp'


--------------------
2017-11-14 08:03:51 - Exception on message: {'id': '02z2vegm6fgn4', 'parent': '02z2ux2xtj4sg', 'time': 1510646631, 'sender': {'id': 'account:01ha19ib9296o', 'name': 'Pouncy Silverkitten', 'server_id': 'heim.2', 'server_era': '02xttnydj5xj4', 'session_id': '746564632d686e72744d593d-ef34bec079d20b1d'}, 'content': '!roomstats', 'edited': None, 'deleted': None}:
Traceback (most recent call last):
  File "heimdall.py", line 316, in <module>
    print(lowerBound.utcfromtimestamp(0))
AttributeError: 'float' object has no attribute 'utcfromtimestamp'


--------------------
2017-11-14 08:04:51 - Exception on message: {'id': '02z2vholy6q68', 'parent': '02z2ux2xtj4sg', 'time': 1510646691, 'sender': {'id': 'account:01ha19ib9296o', 'name': 'Pouncy Silverkitten', 'server_id': 'heim.2', 'server_era': '02xttnydj5xj4', 'session_id': '746564632d686e72744d593d-ef34bec079d20b1d'}, 'content': '!roomstats', 'edited': None, 'deleted': None}:
Traceback (most recent call last):
  File "heimdall.py", line 320, in <module>
    perDayLastFourWeeks = int(last28Days[0]/28)
TypeError: unsupported operand type(s) for /: 'tuple' and 'int'


--------------------
2018-01-22 16:54:20 - Exception on message: {'time': 1516639999, 'next': 1516640029}:
Traceback (most recent call last):
  File "/home/struan/python/karelia/karelia.py", line 177, in parse
    incoming = self.conn.recv()
  File "/usr/lib/python3.6/site-packages/websocket/_core.py", line 293, in recv
    opcode, data = self.recv_data()
  File "/usr/lib/python3.6/site-packages/websocket/_core.py", line 310, in recv_data
    opcode, frame = self.recv_data_frame(control_frame)
  File "/usr/lib/python3.6/site-packages/websocket/_core.py", line 323, in recv_data_frame
    frame = self.recv_frame()
  File "/usr/lib/python3.6/site-packages/websocket/_core.py", line 357, in recv_frame
    return self.frame_buffer.recv_frame()
  File "/usr/lib/python3.6/site-packages/websocket/_abnf.py", line 336, in recv_frame
    self.recv_header()
  File "/usr/lib/python3.6/site-packages/websocket/_abnf.py", line 286, in recv_header
    header = self.recv_strict(2)
  File "/usr/lib/python3.6/site-packages/websocket/_abnf.py", line 371, in recv_strict
    bytes_ = self.recv(min(16384, shortage))
  File "/usr/lib/python3.6/site-packages/websocket/_core.py", line 427, in _recv
    return recv(self.sock, bufsize)
  File "/usr/lib/python3.6/site-packages/websocket/_socket.py", line 80, in recv
    bytes_ = sock.recv(bufsize)
  File "/usr/lib/python3.6/ssl.py", line 994, in recv
    return self.read(buflen)
  File "/usr/lib/python3.6/ssl.py", line 871, in read
    return self._sslobj.read(len, buffer)
  File "/usr/lib/python3.6/ssl.py", line 633, in read
    v = self._sslobj.read(len)
TimeoutError: [Errno 110] Connection timed out

During handling of the above exception, another exception occurred:

Traceback (most recent call last):
  File "heimdall.py", line 213, in <module>
    conn = sqlite3.connect('logs.db')
  File "/home/struan/python/karelia/karelia.py", line 239, in parse
    {'message': 'There was an error parsing the message', 'error': e})
karelia.KareliaException: {'message': 'There was an error parsing the message', 'error': TimeoutError(110, 'Connection timed out')}


--------------------
2018-01-22 16:54:35 - Exception on message: {'time': 1516639999, 'next': 1516640029}:
Traceback (most recent call last):
  File "heimdall.py", line 208, in <module>
    heimdall.disconnect()
  File "/home/struan/python/karelia/karelia.py", line 56, in connect
    "wss://euphoria.io/room/{}/ws".format(self.room))
  File "/usr/lib/python3.6/site-packages/websocket/_core.py", line 487, in create_connection
    websock.connect(url, **options)
  File "/usr/lib/python3.6/site-packages/websocket/_core.py", line 211, in connect
    options.pop('socket', None))
  File "/usr/lib/python3.6/site-packages/websocket/_http.py", line 64, in connect
    hostname, port, is_secure, proxy)
  File "/usr/lib/python3.6/site-packages/websocket/_http.py", line 93, in _get_addrinfo_list
    hostname, port, 0, 0, socket.SOL_TCP)
  File "/usr/lib/python3.6/socket.py", line 745, in getaddrinfo
    for res in _socket.getaddrinfo(host, port, family, type, proto, flags):
socket.gaierror: [Errno -2] Name or service not known


--------------------
2018-01-22 16:54:50 - Exception on message: {'time': 1516639999, 'next': 1516640029}:
Traceback (most recent call last):
  File "heimdall.py", line 208, in <module>
    heimdall.disconnect()
  File "/home/struan/python/karelia/karelia.py", line 56, in connect
    "wss://euphoria.io/room/{}/ws".format(self.room))
  File "/usr/lib/python3.6/site-packages/websocket/_core.py", line 487, in create_connection
    websock.connect(url, **options)
  File "/usr/lib/python3.6/site-packages/websocket/_core.py", line 211, in connect
    options.pop('socket', None))
  File "/usr/lib/python3.6/site-packages/websocket/_http.py", line 64, in connect
    hostname, port, is_secure, proxy)
  File "/usr/lib/python3.6/site-packages/websocket/_http.py", line 93, in _get_addrinfo_list
    hostname, port, 0, 0, socket.SOL_TCP)
  File "/usr/lib/python3.6/socket.py", line 745, in getaddrinfo
    for res in _socket.getaddrinfo(host, port, family, type, proto, flags):
socket.gaierror: [Errno -2] Name or service not known


--------------------
2018-01-22 16:55:05 - Exception on message: {'time': 1516639999, 'next': 1516640029}:
Traceback (most recent call last):
  File "heimdall.py", line 208, in <module>
    heimdall.disconnect()
  File "/home/struan/python/karelia/karelia.py", line 56, in connect
    "wss://euphoria.io/room/{}/ws".format(self.room))
  File "/usr/lib/python3.6/site-packages/websocket/_core.py", line 487, in create_connection
    websock.connect(url, **options)
  File "/usr/lib/python3.6/site-packages/websocket/_core.py", line 211, in connect
    options.pop('socket', None))
  File "/usr/lib/python3.6/site-packages/websocket/_http.py", line 64, in connect
    hostname, port, is_secure, proxy)
  File "/usr/lib/python3.6/site-packages/websocket/_http.py", line 93, in _get_addrinfo_list
    hostname, port, 0, 0, socket.SOL_TCP)
  File "/usr/lib/python3.6/socket.py", line 745, in getaddrinfo
    for res in _socket.getaddrinfo(host, port, family, type, proto, flags):
socket.gaierror: [Errno -2] Name or service not known


--------------------
2018-01-22 16:55:20 - Exception on message: {'time': 1516639999, 'next': 1516640029}:
Traceback (most recent call last):
  File "heimdall.py", line 208, in <module>
    heimdall.disconnect()
  File "/home/struan/python/karelia/karelia.py", line 56, in connect
    "wss://euphoria.io/room/{}/ws".format(self.room))
  File "/usr/lib/python3.6/site-packages/websocket/_core.py", line 487, in create_connection
    websock.connect(url, **options)
  File "/usr/lib/python3.6/site-packages/websocket/_core.py", line 211, in connect
    options.pop('socket', None))
  File "/usr/lib/python3.6/site-packages/websocket/_http.py", line 64, in connect
    hostname, port, is_secure, proxy)
  File "/usr/lib/python3.6/site-packages/websocket/_http.py", line 93, in _get_addrinfo_list
    hostname, port, 0, 0, socket.SOL_TCP)
  File "/usr/lib/python3.6/socket.py", line 745, in getaddrinfo
    for res in _socket.getaddrinfo(host, port, family, type, proto, flags):
socket.gaierror: [Errno -2] Name or service not known


--------------------
2018-01-22 16:55:35 - Exception on message: {'time': 1516639999, 'next': 1516640029}:
Traceback (most recent call last):
  File "heimdall.py", line 208, in <module>
    heimdall.disconnect()
  File "/home/struan/python/karelia/karelia.py", line 56, in connect
    "wss://euphoria.io/room/{}/ws".format(self.room))
  File "/usr/lib/python3.6/site-packages/websocket/_core.py", line 487, in create_connection
    websock.connect(url, **options)
  File "/usr/lib/python3.6/site-packages/websocket/_core.py", line 211, in connect
    options.pop('socket', None))
  File "/usr/lib/python3.6/site-packages/websocket/_http.py", line 64, in connect
    hostname, port, is_secure, proxy)
  File "/usr/lib/python3.6/site-packages/websocket/_http.py", line 93, in _get_addrinfo_list
    hostname, port, 0, 0, socket.SOL_TCP)
  File "/usr/lib/python3.6/socket.py", line 745, in getaddrinfo
    for res in _socket.getaddrinfo(host, port, family, type, proto, flags):
socket.gaierror: [Errno -2] Name or service not known


--------------------
2018-01-22 16:55:50 - Exception on message: {'time': 1516639999, 'next': 1516640029}:
Traceback (most recent call last):
  File "heimdall.py", line 208, in <module>
    heimdall.disconnect()
  File "/home/struan/python/karelia/karelia.py", line 56, in connect
    "wss://euphoria.io/room/{}/ws".format(self.room))
  File "/usr/lib/python3.6/site-packages/websocket/_core.py", line 487, in create_connection
    websock.connect(url, **options)
  File "/usr/lib/python3.6/site-packages/websocket/_core.py", line 211, in connect
    options.pop('socket', None))
  File "/usr/lib/python3.6/site-packages/websocket/_http.py", line 64, in connect
    hostname, port, is_secure, proxy)
  File "/usr/lib/python3.6/site-packages/websocket/_http.py", line 93, in _get_addrinfo_list
    hostname, port, 0, 0, socket.SOL_TCP)
  File "/usr/lib/python3.6/socket.py", line 745, in getaddrinfo
    for res in _socket.getaddrinfo(host, port, family, type, proto, flags):
socket.gaierror: [Errno -2] Name or service not known


--------------------
2018-01-22 16:56:05 - Exception on message: {'time': 1516639999, 'next': 1516640029}:
Traceback (most recent call last):
  File "heimdall.py", line 208, in <module>
    heimdall.disconnect()
  File "/home/struan/python/karelia/karelia.py", line 56, in connect
    "wss://euphoria.io/room/{}/ws".format(self.room))
  File "/usr/lib/python3.6/site-packages/websocket/_core.py", line 487, in create_connection
    websock.connect(url, **options)
  File "/usr/lib/python3.6/site-packages/websocket/_core.py", line 211, in connect
    options.pop('socket', None))
  File "/usr/lib/python3.6/site-packages/websocket/_http.py", line 64, in connect
    hostname, port, is_secure, proxy)
  File "/usr/lib/python3.6/site-packages/websocket/_http.py", line 93, in _get_addrinfo_list
    hostname, port, 0, 0, socket.SOL_TCP)
  File "/usr/lib/python3.6/socket.py", line 745, in getaddrinfo
    for res in _socket.getaddrinfo(host, port, family, type, proto, flags):
socket.gaierror: [Errno -2] Name or service not known


--------------------
2018-01-22 16:56:20 - Exception on message: {'time': 1516639999, 'next': 1516640029}:
Traceback (most recent call last):
  File "heimdall.py", line 208, in <module>
    heimdall.disconnect()
  File "/home/struan/python/karelia/karelia.py", line 56, in connect
    "wss://euphoria.io/room/{}/ws".format(self.room))
  File "/usr/lib/python3.6/site-packages/websocket/_core.py", line 487, in create_connection
    websock.connect(url, **options)
  File "/usr/lib/python3.6/site-packages/websocket/_core.py", line 211, in connect
    options.pop('socket', None))
  File "/usr/lib/python3.6/site-packages/websocket/_http.py", line 64, in connect
    hostname, port, is_secure, proxy)
  File "/usr/lib/python3.6/site-packages/websocket/_http.py", line 93, in _get_addrinfo_list
    hostname, port, 0, 0, socket.SOL_TCP)
  File "/usr/lib/python3.6/socket.py", line 745, in getaddrinfo
    for res in _socket.getaddrinfo(host, port, family, type, proto, flags):
socket.gaierror: [Errno -2] Name or service not known


--------------------
2018-01-22 16:56:35 - Exception on message: {'time': 1516639999, 'next': 1516640029}:
Traceback (most recent call last):
  File "heimdall.py", line 208, in <module>
    heimdall.disconnect()
  File "/home/struan/python/karelia/karelia.py", line 56, in connect
    "wss://euphoria.io/room/{}/ws".format(self.room))
  File "/usr/lib/python3.6/site-packages/websocket/_core.py", line 487, in create_connection
    websock.connect(url, **options)
  File "/usr/lib/python3.6/site-packages/websocket/_core.py", line 211, in connect
    options.pop('socket', None))
  File "/usr/lib/python3.6/site-packages/websocket/_http.py", line 64, in connect
    hostname, port, is_secure, proxy)
  File "/usr/lib/python3.6/site-packages/websocket/_http.py", line 93, in _get_addrinfo_list
    hostname, port, 0, 0, socket.SOL_TCP)
  File "/usr/lib/python3.6/socket.py", line 745, in getaddrinfo
    for res in _socket.getaddrinfo(host, port, family, type, proto, flags):
socket.gaierror: [Errno -2] Name or service not known


--------------------
2018-01-22 16:56:50 - Exception on message: {'time': 1516639999, 'next': 1516640029}:
Traceback (most recent call last):
  File "heimdall.py", line 208, in <module>
    heimdall.disconnect()
  File "/home/struan/python/karelia/karelia.py", line 56, in connect
    "wss://euphoria.io/room/{}/ws".format(self.room))
  File "/usr/lib/python3.6/site-packages/websocket/_core.py", line 487, in create_connection
    websock.connect(url, **options)
  File "/usr/lib/python3.6/site-packages/websocket/_core.py", line 211, in connect
    options.pop('socket', None))
  File "/usr/lib/python3.6/site-packages/websocket/_http.py", line 64, in connect
    hostname, port, is_secure, proxy)
  File "/usr/lib/python3.6/site-packages/websocket/_http.py", line 93, in _get_addrinfo_list
    hostname, port, 0, 0, socket.SOL_TCP)
  File "/usr/lib/python3.6/socket.py", line 745, in getaddrinfo
    for res in _socket.getaddrinfo(host, port, family, type, proto, flags):
socket.gaierror: [Errno -2] Name or service not known


--------------------
2018-01-22 16:57:05 - Exception on message: {'time': 1516639999, 'next': 1516640029}:
Traceback (most recent call last):
  File "heimdall.py", line 208, in <module>
    heimdall.disconnect()
  File "/home/struan/python/karelia/karelia.py", line 56, in connect
    "wss://euphoria.io/room/{}/ws".format(self.room))
  File "/usr/lib/python3.6/site-packages/websocket/_core.py", line 487, in create_connection
    websock.connect(url, **options)
  File "/usr/lib/python3.6/site-packages/websocket/_core.py", line 211, in connect
    options.pop('socket', None))
  File "/usr/lib/python3.6/site-packages/websocket/_http.py", line 64, in connect
    hostname, port, is_secure, proxy)
  File "/usr/lib/python3.6/site-packages/websocket/_http.py", line 93, in _get_addrinfo_list
    hostname, port, 0, 0, socket.SOL_TCP)
  File "/usr/lib/python3.6/socket.py", line 745, in getaddrinfo
    for res in _socket.getaddrinfo(host, port, family, type, proto, flags):
socket.gaierror: [Errno -2] Name or service not known


--------------------
2018-01-22 16:57:20 - Exception on message: {'time': 1516639999, 'next': 1516640029}:
Traceback (most recent call last):
  File "heimdall.py", line 208, in <module>
    heimdall.disconnect()
  File "/home/struan/python/karelia/karelia.py", line 56, in connect
    "wss://euphoria.io/room/{}/ws".format(self.room))
  File "/usr/lib/python3.6/site-packages/websocket/_core.py", line 487, in create_connection
    websock.connect(url, **options)
  File "/usr/lib/python3.6/site-packages/websocket/_core.py", line 211, in connect
    options.pop('socket', None))
  File "/usr/lib/python3.6/site-packages/websocket/_http.py", line 64, in connect
    hostname, port, is_secure, proxy)
  File "/usr/lib/python3.6/site-packages/websocket/_http.py", line 93, in _get_addrinfo_list
    hostname, port, 0, 0, socket.SOL_TCP)
  File "/usr/lib/python3.6/socket.py", line 745, in getaddrinfo
    for res in _socket.getaddrinfo(host, port, family, type, proto, flags):
socket.gaierror: [Errno -2] Name or service not known


--------------------
2018-01-22 16:57:35 - Exception on message: {'time': 1516639999, 'next': 1516640029}:
Traceback (most recent call last):
  File "heimdall.py", line 208, in <module>
    heimdall.disconnect()
  File "/home/struan/python/karelia/karelia.py", line 56, in connect
    "wss://euphoria.io/room/{}/ws".format(self.room))
  File "/usr/lib/python3.6/site-packages/websocket/_core.py", line 487, in create_connection
    websock.connect(url, **options)
  File "/usr/lib/python3.6/site-packages/websocket/_core.py", line 211, in connect
    options.pop('socket', None))
  File "/usr/lib/python3.6/site-packages/websocket/_http.py", line 64, in connect
    hostname, port, is_secure, proxy)
  File "/usr/lib/python3.6/site-packages/websocket/_http.py", line 93, in _get_addrinfo_list
    hostname, port, 0, 0, socket.SOL_TCP)
  File "/usr/lib/python3.6/socket.py", line 745, in getaddrinfo
    for res in _socket.getaddrinfo(host, port, family, type, proto, flags):
socket.gaierror: [Errno -2] Name or service not known


--------------------
2018-01-22 16:57:50 - Exception on message: {'time': 1516639999, 'next': 1516640029}:
Traceback (most recent call last):
  File "heimdall.py", line 208, in <module>
    heimdall.disconnect()
  File "/home/struan/python/karelia/karelia.py", line 56, in connect
    "wss://euphoria.io/room/{}/ws".format(self.room))
  File "/usr/lib/python3.6/site-packages/websocket/_core.py", line 487, in create_connection
    websock.connect(url, **options)
  File "/usr/lib/python3.6/site-packages/websocket/_core.py", line 211, in connect
    options.pop('socket', None))
  File "/usr/lib/python3.6/site-packages/websocket/_http.py", line 64, in connect
    hostname, port, is_secure, proxy)
  File "/usr/lib/python3.6/site-packages/websocket/_http.py", line 93, in _get_addrinfo_list
    hostname, port, 0, 0, socket.SOL_TCP)
  File "/usr/lib/python3.6/socket.py", line 745, in getaddrinfo
    for res in _socket.getaddrinfo(host, port, family, type, proto, flags):
socket.gaierror: [Errno -2] Name or service not known


--------------------
2018-01-22 16:58:05 - Exception on message: {'time': 1516639999, 'next': 1516640029}:
Traceback (most recent call last):
  File "heimdall.py", line 208, in <module>
    heimdall.disconnect()
  File "/home/struan/python/karelia/karelia.py", line 56, in connect
    "wss://euphoria.io/room/{}/ws".format(self.room))
  File "/usr/lib/python3.6/site-packages/websocket/_core.py", line 487, in create_connection
    websock.connect(url, **options)
  File "/usr/lib/python3.6/site-packages/websocket/_core.py", line 211, in connect
    options.pop('socket', None))
  File "/usr/lib/python3.6/site-packages/websocket/_http.py", line 64, in connect
    hostname, port, is_secure, proxy)
  File "/usr/lib/python3.6/site-packages/websocket/_http.py", line 93, in _get_addrinfo_list
    hostname, port, 0, 0, socket.SOL_TCP)
  File "/usr/lib/python3.6/socket.py", line 745, in getaddrinfo
    for res in _socket.getaddrinfo(host, port, family, type, proto, flags):
socket.gaierror: [Errno -2] Name or service not known


--------------------
2018-01-22 16:58:20 - Exception on message: {'time': 1516639999, 'next': 1516640029}:
Traceback (most recent call last):
  File "heimdall.py", line 208, in <module>
    heimdall.disconnect()
  File "/home/struan/python/karelia/karelia.py", line 56, in connect
    "wss://euphoria.io/room/{}/ws".format(self.room))
  File "/usr/lib/python3.6/site-packages/websocket/_core.py", line 487, in create_connection
    websock.connect(url, **options)
  File "/usr/lib/python3.6/site-packages/websocket/_core.py", line 211, in connect
    options.pop('socket', None))
  File "/usr/lib/python3.6/site-packages/websocket/_http.py", line 64, in connect
    hostname, port, is_secure, proxy)
  File "/usr/lib/python3.6/site-packages/websocket/_http.py", line 93, in _get_addrinfo_list
    hostname, port, 0, 0, socket.SOL_TCP)
  File "/usr/lib/python3.6/socket.py", line 745, in getaddrinfo
    for res in _socket.getaddrinfo(host, port, family, type, proto, flags):
socket.gaierror: [Errno -2] Name or service not known


--------------------
2018-01-22 16:58:35 - Exception on message: {'time': 1516639999, 'next': 1516640029}:
Traceback (most recent call last):
  File "heimdall.py", line 208, in <module>
    heimdall.disconnect()
  File "/home/struan/python/karelia/karelia.py", line 56, in connect
    "wss://euphoria.io/room/{}/ws".format(self.room))
  File "/usr/lib/python3.6/site-packages/websocket/_core.py", line 487, in create_connection
    websock.connect(url, **options)
  File "/usr/lib/python3.6/site-packages/websocket/_core.py", line 211, in connect
    options.pop('socket', None))
  File "/usr/lib/python3.6/site-packages/websocket/_http.py", line 64, in connect
    hostname, port, is_secure, proxy)
  File "/usr/lib/python3.6/site-packages/websocket/_http.py", line 93, in _get_addrinfo_list
    hostname, port, 0, 0, socket.SOL_TCP)
  File "/usr/lib/python3.6/socket.py", line 745, in getaddrinfo
    for res in _socket.getaddrinfo(host, port, family, type, proto, flags):
socket.gaierror: [Errno -2] Name or service not known


--------------------
2018-01-22 16:58:50 - Exception on message: {'time': 1516639999, 'next': 1516640029}:
Traceback (most recent call last):
  File "heimdall.py", line 208, in <module>
    heimdall.disconnect()
  File "/home/struan/python/karelia/karelia.py", line 56, in connect
    "wss://euphoria.io/room/{}/ws".format(self.room))
  File "/usr/lib/python3.6/site-packages/websocket/_core.py", line 487, in create_connection
    websock.connect(url, **options)
  File "/usr/lib/python3.6/site-packages/websocket/_core.py", line 211, in connect
    options.pop('socket', None))
  File "/usr/lib/python3.6/site-packages/websocket/_http.py", line 64, in connect
    hostname, port, is_secure, proxy)
  File "/usr/lib/python3.6/site-packages/websocket/_http.py", line 93, in _get_addrinfo_list
    hostname, port, 0, 0, socket.SOL_TCP)
  File "/usr/lib/python3.6/socket.py", line 745, in getaddrinfo
    for res in _socket.getaddrinfo(host, port, family, type, proto, flags):
socket.gaierror: [Errno -2] Name or service not known


--------------------
2018-01-22 16:59:05 - Exception on message: {'time': 1516639999, 'next': 1516640029}:
Traceback (most recent call last):
  File "heimdall.py", line 208, in <module>
    heimdall.disconnect()
  File "/home/struan/python/karelia/karelia.py", line 56, in connect
    "wss://euphoria.io/room/{}/ws".format(self.room))
  File "/usr/lib/python3.6/site-packages/websocket/_core.py", line 487, in create_connection
    websock.connect(url, **options)
  File "/usr/lib/python3.6/site-packages/websocket/_core.py", line 211, in connect
    options.pop('socket', None))
  File "/usr/lib/python3.6/site-packages/websocket/_http.py", line 64, in connect
    hostname, port, is_secure, proxy)
  File "/usr/lib/python3.6/site-packages/websocket/_http.py", line 93, in _get_addrinfo_list
    hostname, port, 0, 0, socket.SOL_TCP)
  File "/usr/lib/python3.6/socket.py", line 745, in getaddrinfo
    for res in _socket.getaddrinfo(host, port, family, type, proto, flags):
socket.gaierror: [Errno -2] Name or service not known


--------------------
2018-01-22 16:59:20 - Exception on message: {'time': 1516639999, 'next': 1516640029}:
Traceback (most recent call last):
  File "heimdall.py", line 208, in <module>
    heimdall.disconnect()
  File "/home/struan/python/karelia/karelia.py", line 56, in connect
    "wss://euphoria.io/room/{}/ws".format(self.room))
  File "/usr/lib/python3.6/site-packages/websocket/_core.py", line 487, in create_connection
    websock.connect(url, **options)
  File "/usr/lib/python3.6/site-packages/websocket/_core.py", line 211, in connect
    options.pop('socket', None))
  File "/usr/lib/python3.6/site-packages/websocket/_http.py", line 64, in connect
    hostname, port, is_secure, proxy)
  File "/usr/lib/python3.6/site-packages/websocket/_http.py", line 93, in _get_addrinfo_list
    hostname, port, 0, 0, socket.SOL_TCP)
  File "/usr/lib/python3.6/socket.py", line 745, in getaddrinfo
    for res in _socket.getaddrinfo(host, port, family, type, proto, flags):
socket.gaierror: [Errno -2] Name or service not known


--------------------
2018-01-22 16:59:35 - Exception on message: {'time': 1516639999, 'next': 1516640029}:
Traceback (most recent call last):
  File "heimdall.py", line 208, in <module>
    heimdall.disconnect()
  File "/home/struan/python/karelia/karelia.py", line 56, in connect
    "wss://euphoria.io/room/{}/ws".format(self.room))
  File "/usr/lib/python3.6/site-packages/websocket/_core.py", line 487, in create_connection
    websock.connect(url, **options)
  File "/usr/lib/python3.6/site-packages/websocket/_core.py", line 211, in connect
    options.pop('socket', None))
  File "/usr/lib/python3.6/site-packages/websocket/_http.py", line 64, in connect
    hostname, port, is_secure, proxy)
  File "/usr/lib/python3.6/site-packages/websocket/_http.py", line 93, in _get_addrinfo_list
    hostname, port, 0, 0, socket.SOL_TCP)
  File "/usr/lib/python3.6/socket.py", line 745, in getaddrinfo
    for res in _socket.getaddrinfo(host, port, family, type, proto, flags):
socket.gaierror: [Errno -2] Name or service not known


--------------------
2018-01-22 16:59:50 - Exception on message: {'time': 1516639999, 'next': 1516640029}:
Traceback (most recent call last):
  File "heimdall.py", line 208, in <module>
    heimdall.disconnect()
  File "/home/struan/python/karelia/karelia.py", line 56, in connect
    "wss://euphoria.io/room/{}/ws".format(self.room))
  File "/usr/lib/python3.6/site-packages/websocket/_core.py", line 487, in create_connection
    websock.connect(url, **options)
  File "/usr/lib/python3.6/site-packages/websocket/_core.py", line 211, in connect
    options.pop('socket', None))
  File "/usr/lib/python3.6/site-packages/websocket/_http.py", line 64, in connect
    hostname, port, is_secure, proxy)
  File "/usr/lib/python3.6/site-packages/websocket/_http.py", line 93, in _get_addrinfo_list
    hostname, port, 0, 0, socket.SOL_TCP)
  File "/usr/lib/python3.6/socket.py", line 745, in getaddrinfo
    for res in _socket.getaddrinfo(host, port, family, type, proto, flags):
socket.gaierror: [Errno -2] Name or service not known


--------------------
2018-01-22 17:00:05 - Exception on message: {'time': 1516639999, 'next': 1516640029}:
Traceback (most recent call last):
  File "heimdall.py", line 208, in <module>
    heimdall.disconnect()
  File "/home/struan/python/karelia/karelia.py", line 56, in connect
    "wss://euphoria.io/room/{}/ws".format(self.room))
  File "/usr/lib/python3.6/site-packages/websocket/_core.py", line 487, in create_connection
    websock.connect(url, **options)
  File "/usr/lib/python3.6/site-packages/websocket/_core.py", line 211, in connect
    options.pop('socket', None))
  File "/usr/lib/python3.6/site-packages/websocket/_http.py", line 64, in connect
    hostname, port, is_secure, proxy)
  File "/usr/lib/python3.6/site-packages/websocket/_http.py", line 93, in _get_addrinfo_list
    hostname, port, 0, 0, socket.SOL_TCP)
  File "/usr/lib/python3.6/socket.py", line 745, in getaddrinfo
    for res in _socket.getaddrinfo(host, port, family, type, proto, flags):
socket.gaierror: [Errno -2] Name or service not known


--------------------
2018-01-22 17:00:20 - Exception on message: {'time': 1516639999, 'next': 1516640029}:
Traceback (most recent call last):
  File "heimdall.py", line 208, in <module>
    heimdall.disconnect()
  File "/home/struan/python/karelia/karelia.py", line 56, in connect
    "wss://euphoria.io/room/{}/ws".format(self.room))
  File "/usr/lib/python3.6/site-packages/websocket/_core.py", line 487, in create_connection
    websock.connect(url, **options)
  File "/usr/lib/python3.6/site-packages/websocket/_core.py", line 211, in connect
    options.pop('socket', None))
  File "/usr/lib/python3.6/site-packages/websocket/_http.py", line 64, in connect
    hostname, port, is_secure, proxy)
  File "/usr/lib/python3.6/site-packages/websocket/_http.py", line 93, in _get_addrinfo_list
    hostname, port, 0, 0, socket.SOL_TCP)
  File "/usr/lib/python3.6/socket.py", line 745, in getaddrinfo
    for res in _socket.getaddrinfo(host, port, family, type, proto, flags):
socket.gaierror: [Errno -2] Name or service not known


--------------------
2018-01-22 17:00:35 - Exception on message: {'time': 1516639999, 'next': 1516640029}:
Traceback (most recent call last):
  File "heimdall.py", line 208, in <module>
    heimdall.disconnect()
  File "/home/struan/python/karelia/karelia.py", line 56, in connect
    "wss://euphoria.io/room/{}/ws".format(self.room))
  File "/usr/lib/python3.6/site-packages/websocket/_core.py", line 487, in create_connection
    websock.connect(url, **options)
  File "/usr/lib/python3.6/site-packages/websocket/_core.py", line 211, in connect
    options.pop('socket', None))
  File "/usr/lib/python3.6/site-packages/websocket/_http.py", line 64, in connect
    hostname, port, is_secure, proxy)
  File "/usr/lib/python3.6/site-packages/websocket/_http.py", line 93, in _get_addrinfo_list
    hostname, port, 0, 0, socket.SOL_TCP)
  File "/usr/lib/python3.6/socket.py", line 745, in getaddrinfo
    for res in _socket.getaddrinfo(host, port, family, type, proto, flags):
socket.gaierror: [Errno -2] Name or service not known


--------------------
2018-01-22 17:00:50 - Exception on message: {'time': 1516639999, 'next': 1516640029}:
Traceback (most recent call last):
  File "heimdall.py", line 208, in <module>
    heimdall.disconnect()
  File "/home/struan/python/karelia/karelia.py", line 56, in connect
    "wss://euphoria.io/room/{}/ws".format(self.room))
  File "/usr/lib/python3.6/site-packages/websocket/_core.py", line 487, in create_connection
    websock.connect(url, **options)
  File "/usr/lib/python3.6/site-packages/websocket/_core.py", line 211, in connect
    options.pop('socket', None))
  File "/usr/lib/python3.6/site-packages/websocket/_http.py", line 64, in connect
    hostname, port, is_secure, proxy)
  File "/usr/lib/python3.6/site-packages/websocket/_http.py", line 93, in _get_addrinfo_list
    hostname, port, 0, 0, socket.SOL_TCP)
  File "/usr/lib/python3.6/socket.py", line 745, in getaddrinfo
    for res in _socket.getaddrinfo(host, port, family, type, proto, flags):
socket.gaierror: [Errno -2] Name or service not known


--------------------
2018-01-22 17:01:05 - Exception on message: {'time': 1516639999, 'next': 1516640029}:
Traceback (most recent call last):
  File "heimdall.py", line 208, in <module>
    heimdall.disconnect()
  File "/home/struan/python/karelia/karelia.py", line 56, in connect
    "wss://euphoria.io/room/{}/ws".format(self.room))
  File "/usr/lib/python3.6/site-packages/websocket/_core.py", line 487, in create_connection
    websock.connect(url, **options)
  File "/usr/lib/python3.6/site-packages/websocket/_core.py", line 211, in connect
    options.pop('socket', None))
  File "/usr/lib/python3.6/site-packages/websocket/_http.py", line 64, in connect
    hostname, port, is_secure, proxy)
  File "/usr/lib/python3.6/site-packages/websocket/_http.py", line 93, in _get_addrinfo_list
    hostname, port, 0, 0, socket.SOL_TCP)
  File "/usr/lib/python3.6/socket.py", line 745, in getaddrinfo
    for res in _socket.getaddrinfo(host, port, family, type, proto, flags):
socket.gaierror: [Errno -2] Name or service not known


--------------------
2018-01-22 17:01:20 - Exception on message: {'time': 1516639999, 'next': 1516640029}:
Traceback (most recent call last):
  File "heimdall.py", line 208, in <module>
    heimdall.disconnect()
  File "/home/struan/python/karelia/karelia.py", line 56, in connect
    "wss://euphoria.io/room/{}/ws".format(self.room))
  File "/usr/lib/python3.6/site-packages/websocket/_core.py", line 487, in create_connection
    websock.connect(url, **options)
  File "/usr/lib/python3.6/site-packages/websocket/_core.py", line 211, in connect
    options.pop('socket', None))
  File "/usr/lib/python3.6/site-packages/websocket/_http.py", line 64, in connect
    hostname, port, is_secure, proxy)
  File "/usr/lib/python3.6/site-packages/websocket/_http.py", line 93, in _get_addrinfo_list
    hostname, port, 0, 0, socket.SOL_TCP)
  File "/usr/lib/python3.6/socket.py", line 745, in getaddrinfo
    for res in _socket.getaddrinfo(host, port, family, type, proto, flags):
socket.gaierror: [Errno -2] Name or service not known


--------------------
2018-01-22 17:01:35 - Exception on message: {'time': 1516639999, 'next': 1516640029}:
Traceback (most recent call last):
  File "heimdall.py", line 208, in <module>
    heimdall.disconnect()
  File "/home/struan/python/karelia/karelia.py", line 56, in connect
    "wss://euphoria.io/room/{}/ws".format(self.room))
  File "/usr/lib/python3.6/site-packages/websocket/_core.py", line 487, in create_connection
    websock.connect(url, **options)
  File "/usr/lib/python3.6/site-packages/websocket/_core.py", line 211, in connect
    options.pop('socket', None))
  File "/usr/lib/python3.6/site-packages/websocket/_http.py", line 64, in connect
    hostname, port, is_secure, proxy)
  File "/usr/lib/python3.6/site-packages/websocket/_http.py", line 93, in _get_addrinfo_list
    hostname, port, 0, 0, socket.SOL_TCP)
  File "/usr/lib/python3.6/socket.py", line 745, in getaddrinfo
    for res in _socket.getaddrinfo(host, port, family, type, proto, flags):
socket.gaierror: [Errno -2] Name or service not known


--------------------
2018-01-22 17:01:50 - Exception on message: {'time': 1516639999, 'next': 1516640029}:
Traceback (most recent call last):
  File "heimdall.py", line 208, in <module>
    heimdall.disconnect()
  File "/home/struan/python/karelia/karelia.py", line 56, in connect
    "wss://euphoria.io/room/{}/ws".format(self.room))
  File "/usr/lib/python3.6/site-packages/websocket/_core.py", line 487, in create_connection
    websock.connect(url, **options)
  File "/usr/lib/python3.6/site-packages/websocket/_core.py", line 211, in connect
    options.pop('socket', None))
  File "/usr/lib/python3.6/site-packages/websocket/_http.py", line 64, in connect
    hostname, port, is_secure, proxy)
  File "/usr/lib/python3.6/site-packages/websocket/_http.py", line 93, in _get_addrinfo_list
    hostname, port, 0, 0, socket.SOL_TCP)
  File "/usr/lib/python3.6/socket.py", line 745, in getaddrinfo
    for res in _socket.getaddrinfo(host, port, family, type, proto, flags):
socket.gaierror: [Errno -2] Name or service not known


--------------------
2018-01-22 17:02:05 - Exception on message: {'time': 1516639999, 'next': 1516640029}:
Traceback (most recent call last):
  File "heimdall.py", line 208, in <module>
    heimdall.disconnect()
  File "/home/struan/python/karelia/karelia.py", line 56, in connect
    "wss://euphoria.io/room/{}/ws".format(self.room))
  File "/usr/lib/python3.6/site-packages/websocket/_core.py", line 487, in create_connection
    websock.connect(url, **options)
  File "/usr/lib/python3.6/site-packages/websocket/_core.py", line 211, in connect
    options.pop('socket', None))
  File "/usr/lib/python3.6/site-packages/websocket/_http.py", line 64, in connect
    hostname, port, is_secure, proxy)
  File "/usr/lib/python3.6/site-packages/websocket/_http.py", line 93, in _get_addrinfo_list
    hostname, port, 0, 0, socket.SOL_TCP)
  File "/usr/lib/python3.6/socket.py", line 745, in getaddrinfo
    for res in _socket.getaddrinfo(host, port, family, type, proto, flags):
socket.gaierror: [Errno -2] Name or service not known


--------------------
2018-01-22 17:02:20 - Exception on message: {'time': 1516639999, 'next': 1516640029}:
Traceback (most recent call last):
  File "heimdall.py", line 208, in <module>
    heimdall.disconnect()
  File "/home/struan/python/karelia/karelia.py", line 56, in connect
    "wss://euphoria.io/room/{}/ws".format(self.room))
  File "/usr/lib/python3.6/site-packages/websocket/_core.py", line 487, in create_connection
    websock.connect(url, **options)
  File "/usr/lib/python3.6/site-packages/websocket/_core.py", line 211, in connect
    options.pop('socket', None))
  File "/usr/lib/python3.6/site-packages/websocket/_http.py", line 64, in connect
    hostname, port, is_secure, proxy)
  File "/usr/lib/python3.6/site-packages/websocket/_http.py", line 93, in _get_addrinfo_list
    hostname, port, 0, 0, socket.SOL_TCP)
  File "/usr/lib/python3.6/socket.py", line 745, in getaddrinfo
    for res in _socket.getaddrinfo(host, port, family, type, proto, flags):
socket.gaierror: [Errno -2] Name or service not known


--------------------
2018-01-22 17:02:35 - Exception on message: {'time': 1516639999, 'next': 1516640029}:
Traceback (most recent call last):
  File "heimdall.py", line 208, in <module>
    heimdall.disconnect()
  File "/home/struan/python/karelia/karelia.py", line 56, in connect
    "wss://euphoria.io/room/{}/ws".format(self.room))
  File "/usr/lib/python3.6/site-packages/websocket/_core.py", line 487, in create_connection
    websock.connect(url, **options)
  File "/usr/lib/python3.6/site-packages/websocket/_core.py", line 211, in connect
    options.pop('socket', None))
  File "/usr/lib/python3.6/site-packages/websocket/_http.py", line 64, in connect
    hostname, port, is_secure, proxy)
  File "/usr/lib/python3.6/site-packages/websocket/_http.py", line 93, in _get_addrinfo_list
    hostname, port, 0, 0, socket.SOL_TCP)
  File "/usr/lib/python3.6/socket.py", line 745, in getaddrinfo
    for res in _socket.getaddrinfo(host, port, family, type, proto, flags):
socket.gaierror: [Errno -2] Name or service not known


--------------------
2018-01-22 17:02:51 - Exception on message: {'time': 1516639999, 'next': 1516640029}:
Traceback (most recent call last):
  File "heimdall.py", line 208, in <module>
    heimdall.disconnect()
  File "/home/struan/python/karelia/karelia.py", line 56, in connect
    "wss://euphoria.io/room/{}/ws".format(self.room))
  File "/usr/lib/python3.6/site-packages/websocket/_core.py", line 487, in create_connection
    websock.connect(url, **options)
  File "/usr/lib/python3.6/site-packages/websocket/_core.py", line 211, in connect
    options.pop('socket', None))
  File "/usr/lib/python3.6/site-packages/websocket/_http.py", line 64, in connect
    hostname, port, is_secure, proxy)
  File "/usr/lib/python3.6/site-packages/websocket/_http.py", line 93, in _get_addrinfo_list
    hostname, port, 0, 0, socket.SOL_TCP)
  File "/usr/lib/python3.6/socket.py", line 745, in getaddrinfo
    for res in _socket.getaddrinfo(host, port, family, type, proto, flags):
socket.gaierror: [Errno -2] Name or service not known


--------------------
2018-01-22 17:03:06 - Exception on message: {'time': 1516639999, 'next': 1516640029}:
Traceback (most recent call last):
  File "heimdall.py", line 208, in <module>
    heimdall.disconnect()
  File "/home/struan/python/karelia/karelia.py", line 56, in connect
    "wss://euphoria.io/room/{}/ws".format(self.room))
  File "/usr/lib/python3.6/site-packages/websocket/_core.py", line 487, in create_connection
    websock.connect(url, **options)
  File "/usr/lib/python3.6/site-packages/websocket/_core.py", line 211, in connect
    options.pop('socket', None))
  File "/usr/lib/python3.6/site-packages/websocket/_http.py", line 64, in connect
    hostname, port, is_secure, proxy)
  File "/usr/lib/python3.6/site-packages/websocket/_http.py", line 93, in _get_addrinfo_list
    hostname, port, 0, 0, socket.SOL_TCP)
  File "/usr/lib/python3.6/socket.py", line 745, in getaddrinfo
    for res in _socket.getaddrinfo(host, port, family, type, proto, flags):
socket.gaierror: [Errno -2] Name or service not known


--------------------
2018-01-22 17:03:21 - Exception on message: {'time': 1516639999, 'next': 1516640029}:
Traceback (most recent call last):
  File "heimdall.py", line 208, in <module>
    heimdall.disconnect()
  File "/home/struan/python/karelia/karelia.py", line 56, in connect
    "wss://euphoria.io/room/{}/ws".format(self.room))
  File "/usr/lib/python3.6/site-packages/websocket/_core.py", line 487, in create_connection
    websock.connect(url, **options)
  File "/usr/lib/python3.6/site-packages/websocket/_core.py", line 211, in connect
    options.pop('socket', None))
  File "/usr/lib/python3.6/site-packages/websocket/_http.py", line 64, in connect
    hostname, port, is_secure, proxy)
  File "/usr/lib/python3.6/site-packages/websocket/_http.py", line 93, in _get_addrinfo_list
    hostname, port, 0, 0, socket.SOL_TCP)
  File "/usr/lib/python3.6/socket.py", line 745, in getaddrinfo
    for res in _socket.getaddrinfo(host, port, family, type, proto, flags):
socket.gaierror: [Errno -2] Name or service not known


--------------------
2018-01-22 17:03:36 - Exception on message: {'time': 1516639999, 'next': 1516640029}:
Traceback (most recent call last):
  File "heimdall.py", line 208, in <module>
    heimdall.disconnect()
  File "/home/struan/python/karelia/karelia.py", line 56, in connect
    "wss://euphoria.io/room/{}/ws".format(self.room))
  File "/usr/lib/python3.6/site-packages/websocket/_core.py", line 487, in create_connection
    websock.connect(url, **options)
  File "/usr/lib/python3.6/site-packages/websocket/_core.py", line 211, in connect
    options.pop('socket', None))
  File "/usr/lib/python3.6/site-packages/websocket/_http.py", line 64, in connect
    hostname, port, is_secure, proxy)
  File "/usr/lib/python3.6/site-packages/websocket/_http.py", line 93, in _get_addrinfo_list
    hostname, port, 0, 0, socket.SOL_TCP)
  File "/usr/lib/python3.6/socket.py", line 745, in getaddrinfo
    for res in _socket.getaddrinfo(host, port, family, type, proto, flags):
socket.gaierror: [Errno -2] Name or service not known


--------------------
2018-01-22 17:03:51 - Exception on message: {'time': 1516639999, 'next': 1516640029}:
Traceback (most recent call last):
  File "heimdall.py", line 208, in <module>
    heimdall.disconnect()
  File "/home/struan/python/karelia/karelia.py", line 56, in connect
    "wss://euphoria.io/room/{}/ws".format(self.room))
  File "/usr/lib/python3.6/site-packages/websocket/_core.py", line 487, in create_connection
    websock.connect(url, **options)
  File "/usr/lib/python3.6/site-packages/websocket/_core.py", line 211, in connect
    options.pop('socket', None))
  File "/usr/lib/python3.6/site-packages/websocket/_http.py", line 64, in connect
    hostname, port, is_secure, proxy)
  File "/usr/lib/python3.6/site-packages/websocket/_http.py", line 93, in _get_addrinfo_list
    hostname, port, 0, 0, socket.SOL_TCP)
  File "/usr/lib/python3.6/socket.py", line 745, in getaddrinfo
    for res in _socket.getaddrinfo(host, port, family, type, proto, flags):
socket.gaierror: [Errno -2] Name or service not known


--------------------
2018-01-22 17:04:06 - Exception on message: {'time': 1516639999, 'next': 1516640029}:
Traceback (most recent call last):
  File "heimdall.py", line 208, in <module>
    heimdall.disconnect()
  File "/home/struan/python/karelia/karelia.py", line 56, in connect
    "wss://euphoria.io/room/{}/ws".format(self.room))
  File "/usr/lib/python3.6/site-packages/websocket/_core.py", line 487, in create_connection
    websock.connect(url, **options)
  File "/usr/lib/python3.6/site-packages/websocket/_core.py", line 211, in connect
    options.pop('socket', None))
  File "/usr/lib/python3.6/site-packages/websocket/_http.py", line 64, in connect
    hostname, port, is_secure, proxy)
  File "/usr/lib/python3.6/site-packages/websocket/_http.py", line 93, in _get_addrinfo_list
    hostname, port, 0, 0, socket.SOL_TCP)
  File "/usr/lib/python3.6/socket.py", line 745, in getaddrinfo
    for res in _socket.getaddrinfo(host, port, family, type, proto, flags):
socket.gaierror: [Errno -2] Name or service not known


--------------------
2018-01-22 17:04:21 - Exception on message: {'time': 1516639999, 'next': 1516640029}:
Traceback (most recent call last):
  File "heimdall.py", line 208, in <module>
    heimdall.disconnect()
  File "/home/struan/python/karelia/karelia.py", line 56, in connect
    "wss://euphoria.io/room/{}/ws".format(self.room))
  File "/usr/lib/python3.6/site-packages/websocket/_core.py", line 487, in create_connection
    websock.connect(url, **options)
  File "/usr/lib/python3.6/site-packages/websocket/_core.py", line 211, in connect
    options.pop('socket', None))
  File "/usr/lib/python3.6/site-packages/websocket/_http.py", line 64, in connect
    hostname, port, is_secure, proxy)
  File "/usr/lib/python3.6/site-packages/websocket/_http.py", line 93, in _get_addrinfo_list
    hostname, port, 0, 0, socket.SOL_TCP)
  File "/usr/lib/python3.6/socket.py", line 745, in getaddrinfo
    for res in _socket.getaddrinfo(host, port, family, type, proto, flags):
socket.gaierror: [Errno -2] Name or service not known


--------------------
2018-01-22 17:04:36 - Exception on message: {'time': 1516639999, 'next': 1516640029}:
Traceback (most recent call last):
  File "heimdall.py", line 208, in <module>
    heimdall.disconnect()
  File "/home/struan/python/karelia/karelia.py", line 56, in connect
    "wss://euphoria.io/room/{}/ws".format(self.room))
  File "/usr/lib/python3.6/site-packages/websocket/_core.py", line 487, in create_connection
    websock.connect(url, **options)
  File "/usr/lib/python3.6/site-packages/websocket/_core.py", line 211, in connect
    options.pop('socket', None))
  File "/usr/lib/python3.6/site-packages/websocket/_http.py", line 64, in connect
    hostname, port, is_secure, proxy)
  File "/usr/lib/python3.6/site-packages/websocket/_http.py", line 93, in _get_addrinfo_list
    hostname, port, 0, 0, socket.SOL_TCP)
  File "/usr/lib/python3.6/socket.py", line 745, in getaddrinfo
    for res in _socket.getaddrinfo(host, port, family, type, proto, flags):
socket.gaierror: [Errno -2] Name or service not known


--------------------
2018-01-22 17:04:51 - Exception on message: {'time': 1516639999, 'next': 1516640029}:
Traceback (most recent call last):
  File "heimdall.py", line 208, in <module>
    heimdall.disconnect()
  File "/home/struan/python/karelia/karelia.py", line 56, in connect
    "wss://euphoria.io/room/{}/ws".format(self.room))
  File "/usr/lib/python3.6/site-packages/websocket/_core.py", line 487, in create_connection
    websock.connect(url, **options)
  File "/usr/lib/python3.6/site-packages/websocket/_core.py", line 211, in connect
    options.pop('socket', None))
  File "/usr/lib/python3.6/site-packages/websocket/_http.py", line 64, in connect
    hostname, port, is_secure, proxy)
  File "/usr/lib/python3.6/site-packages/websocket/_http.py", line 93, in _get_addrinfo_list
    hostname, port, 0, 0, socket.SOL_TCP)
  File "/usr/lib/python3.6/socket.py", line 745, in getaddrinfo
    for res in _socket.getaddrinfo(host, port, family, type, proto, flags):
socket.gaierror: [Errno -2] Name or service not known


--------------------
2018-01-22 17:05:06 - Exception on message: {'time': 1516639999, 'next': 1516640029}:
Traceback (most recent call last):
  File "heimdall.py", line 208, in <module>
    heimdall.disconnect()
  File "/home/struan/python/karelia/karelia.py", line 56, in connect
    "wss://euphoria.io/room/{}/ws".format(self.room))
  File "/usr/lib/python3.6/site-packages/websocket/_core.py", line 487, in create_connection
    websock.connect(url, **options)
  File "/usr/lib/python3.6/site-packages/websocket/_core.py", line 211, in connect
    options.pop('socket', None))
  File "/usr/lib/python3.6/site-packages/websocket/_http.py", line 64, in connect
    hostname, port, is_secure, proxy)
  File "/usr/lib/python3.6/site-packages/websocket/_http.py", line 93, in _get_addrinfo_list
    hostname, port, 0, 0, socket.SOL_TCP)
  File "/usr/lib/python3.6/socket.py", line 745, in getaddrinfo
    for res in _socket.getaddrinfo(host, port, family, type, proto, flags):
socket.gaierror: [Errno -2] Name or service not known


--------------------
2018-01-22 17:05:21 - Exception on message: {'time': 1516639999, 'next': 1516640029}:
Traceback (most recent call last):
  File "heimdall.py", line 208, in <module>
    heimdall.disconnect()
  File "/home/struan/python/karelia/karelia.py", line 56, in connect
    "wss://euphoria.io/room/{}/ws".format(self.room))
  File "/usr/lib/python3.6/site-packages/websocket/_core.py", line 487, in create_connection
    websock.connect(url, **options)
  File "/usr/lib/python3.6/site-packages/websocket/_core.py", line 211, in connect
    options.pop('socket', None))
  File "/usr/lib/python3.6/site-packages/websocket/_http.py", line 64, in connect
    hostname, port, is_secure, proxy)
  File "/usr/lib/python3.6/site-packages/websocket/_http.py", line 93, in _get_addrinfo_list
    hostname, port, 0, 0, socket.SOL_TCP)
  File "/usr/lib/python3.6/socket.py", line 745, in getaddrinfo
    for res in _socket.getaddrinfo(host, port, family, type, proto, flags):
socket.gaierror: [Errno -2] Name or service not known


--------------------
2018-01-22 17:05:36 - Exception on message: {'time': 1516639999, 'next': 1516640029}:
Traceback (most recent call last):
  File "heimdall.py", line 208, in <module>
    heimdall.disconnect()
  File "/home/struan/python/karelia/karelia.py", line 56, in connect
    "wss://euphoria.io/room/{}/ws".format(self.room))
  File "/usr/lib/python3.6/site-packages/websocket/_core.py", line 487, in create_connection
    websock.connect(url, **options)
  File "/usr/lib/python3.6/site-packages/websocket/_core.py", line 211, in connect
    options.pop('socket', None))
  File "/usr/lib/python3.6/site-packages/websocket/_http.py", line 64, in connect
    hostname, port, is_secure, proxy)
  File "/usr/lib/python3.6/site-packages/websocket/_http.py", line 93, in _get_addrinfo_list
    hostname, port, 0, 0, socket.SOL_TCP)
  File "/usr/lib/python3.6/socket.py", line 745, in getaddrinfo
    for res in _socket.getaddrinfo(host, port, family, type, proto, flags):
socket.gaierror: [Errno -2] Name or service not known


--------------------
2018-01-22 17:05:51 - Exception on message: {'time': 1516639999, 'next': 1516640029}:
Traceback (most recent call last):
  File "heimdall.py", line 208, in <module>
    heimdall.disconnect()
  File "/home/struan/python/karelia/karelia.py", line 56, in connect
    "wss://euphoria.io/room/{}/ws".format(self.room))
  File "/usr/lib/python3.6/site-packages/websocket/_core.py", line 487, in create_connection
    websock.connect(url, **options)
  File "/usr/lib/python3.6/site-packages/websocket/_core.py", line 211, in connect
    options.pop('socket', None))
  File "/usr/lib/python3.6/site-packages/websocket/_http.py", line 64, in connect
    hostname, port, is_secure, proxy)
  File "/usr/lib/python3.6/site-packages/websocket/_http.py", line 93, in _get_addrinfo_list
    hostname, port, 0, 0, socket.SOL_TCP)
  File "/usr/lib/python3.6/socket.py", line 745, in getaddrinfo
    for res in _socket.getaddrinfo(host, port, family, type, proto, flags):
socket.gaierror: [Errno -2] Name or service not known


--------------------
2018-01-22 17:06:06 - Exception on message: {'time': 1516639999, 'next': 1516640029}:
Traceback (most recent call last):
  File "heimdall.py", line 208, in <module>
    heimdall.disconnect()
  File "/home/struan/python/karelia/karelia.py", line 56, in connect
    "wss://euphoria.io/room/{}/ws".format(self.room))
  File "/usr/lib/python3.6/site-packages/websocket/_core.py", line 487, in create_connection
    websock.connect(url, **options)
  File "/usr/lib/python3.6/site-packages/websocket/_core.py", line 211, in connect
    options.pop('socket', None))
  File "/usr/lib/python3.6/site-packages/websocket/_http.py", line 64, in connect
    hostname, port, is_secure, proxy)
  File "/usr/lib/python3.6/site-packages/websocket/_http.py", line 93, in _get_addrinfo_list
    hostname, port, 0, 0, socket.SOL_TCP)
  File "/usr/lib/python3.6/socket.py", line 745, in getaddrinfo
    for res in _socket.getaddrinfo(host, port, family, type, proto, flags):
socket.gaierror: [Errno -2] Name or service not known


--------------------
2018-01-22 17:06:21 - Exception on message: {'time': 1516639999, 'next': 1516640029}:
Traceback (most recent call last):
  File "heimdall.py", line 208, in <module>
    heimdall.disconnect()
  File "/home/struan/python/karelia/karelia.py", line 56, in connect
    "wss://euphoria.io/room/{}/ws".format(self.room))
  File "/usr/lib/python3.6/site-packages/websocket/_core.py", line 487, in create_connection
    websock.connect(url, **options)
  File "/usr/lib/python3.6/site-packages/websocket/_core.py", line 211, in connect
    options.pop('socket', None))
  File "/usr/lib/python3.6/site-packages/websocket/_http.py", line 64, in connect
    hostname, port, is_secure, proxy)
  File "/usr/lib/python3.6/site-packages/websocket/_http.py", line 93, in _get_addrinfo_list
    hostname, port, 0, 0, socket.SOL_TCP)
  File "/usr/lib/python3.6/socket.py", line 745, in getaddrinfo
    for res in _socket.getaddrinfo(host, port, family, type, proto, flags):
socket.gaierror: [Errno -2] Name or service not known


--------------------
2018-01-22 17:06:36 - Exception on message: {'time': 1516639999, 'next': 1516640029}:
Traceback (most recent call last):
  File "heimdall.py", line 208, in <module>
    heimdall.disconnect()
  File "/home/struan/python/karelia/karelia.py", line 56, in connect
    "wss://euphoria.io/room/{}/ws".format(self.room))
  File "/usr/lib/python3.6/site-packages/websocket/_core.py", line 487, in create_connection
    websock.connect(url, **options)
  File "/usr/lib/python3.6/site-packages/websocket/_core.py", line 211, in connect
    options.pop('socket', None))
  File "/usr/lib/python3.6/site-packages/websocket/_http.py", line 64, in connect
    hostname, port, is_secure, proxy)
  File "/usr/lib/python3.6/site-packages/websocket/_http.py", line 93, in _get_addrinfo_list
    hostname, port, 0, 0, socket.SOL_TCP)
  File "/usr/lib/python3.6/socket.py", line 745, in getaddrinfo
    for res in _socket.getaddrinfo(host, port, family, type, proto, flags):
socket.gaierror: [Errno -2] Name or service not known


--------------------
2018-01-22 17:06:51 - Exception on message: {'time': 1516639999, 'next': 1516640029}:
Traceback (most recent call last):
  File "heimdall.py", line 208, in <module>
    heimdall.disconnect()
  File "/home/struan/python/karelia/karelia.py", line 56, in connect
    "wss://euphoria.io/room/{}/ws".format(self.room))
  File "/usr/lib/python3.6/site-packages/websocket/_core.py", line 487, in create_connection
    websock.connect(url, **options)
  File "/usr/lib/python3.6/site-packages/websocket/_core.py", line 211, in connect
    options.pop('socket', None))
  File "/usr/lib/python3.6/site-packages/websocket/_http.py", line 64, in connect
    hostname, port, is_secure, proxy)
  File "/usr/lib/python3.6/site-packages/websocket/_http.py", line 93, in _get_addrinfo_list
    hostname, port, 0, 0, socket.SOL_TCP)
  File "/usr/lib/python3.6/socket.py", line 745, in getaddrinfo
    for res in _socket.getaddrinfo(host, port, family, type, proto, flags):
socket.gaierror: [Errno -2] Name or service not known


--------------------
2018-01-22 17:07:06 - Exception on message: {'time': 1516639999, 'next': 1516640029}:
Traceback (most recent call last):
  File "heimdall.py", line 208, in <module>
    heimdall.disconnect()
  File "/home/struan/python/karelia/karelia.py", line 56, in connect
    "wss://euphoria.io/room/{}/ws".format(self.room))
  File "/usr/lib/python3.6/site-packages/websocket/_core.py", line 487, in create_connection
    websock.connect(url, **options)
  File "/usr/lib/python3.6/site-packages/websocket/_core.py", line 211, in connect
    options.pop('socket', None))
  File "/usr/lib/python3.6/site-packages/websocket/_http.py", line 64, in connect
    hostname, port, is_secure, proxy)
  File "/usr/lib/python3.6/site-packages/websocket/_http.py", line 93, in _get_addrinfo_list
    hostname, port, 0, 0, socket.SOL_TCP)
  File "/usr/lib/python3.6/socket.py", line 745, in getaddrinfo
    for res in _socket.getaddrinfo(host, port, family, type, proto, flags):
socket.gaierror: [Errno -2] Name or service not known


--------------------
2018-01-22 17:07:21 - Exception on message: {'time': 1516639999, 'next': 1516640029}:
Traceback (most recent call last):
  File "heimdall.py", line 208, in <module>
    heimdall.disconnect()
  File "/home/struan/python/karelia/karelia.py", line 56, in connect
    "wss://euphoria.io/room/{}/ws".format(self.room))
  File "/usr/lib/python3.6/site-packages/websocket/_core.py", line 487, in create_connection
    websock.connect(url, **options)
  File "/usr/lib/python3.6/site-packages/websocket/_core.py", line 211, in connect
    options.pop('socket', None))
  File "/usr/lib/python3.6/site-packages/websocket/_http.py", line 64, in connect
    hostname, port, is_secure, proxy)
  File "/usr/lib/python3.6/site-packages/websocket/_http.py", line 93, in _get_addrinfo_list
    hostname, port, 0, 0, socket.SOL_TCP)
  File "/usr/lib/python3.6/socket.py", line 745, in getaddrinfo
    for res in _socket.getaddrinfo(host, port, family, type, proto, flags):
socket.gaierror: [Errno -2] Name or service not known


--------------------
2018-01-22 17:07:36 - Exception on message: {'time': 1516639999, 'next': 1516640029}:
Traceback (most recent call last):
  File "heimdall.py", line 208, in <module>
    heimdall.disconnect()
  File "/home/struan/python/karelia/karelia.py", line 56, in connect
    "wss://euphoria.io/room/{}/ws".format(self.room))
  File "/usr/lib/python3.6/site-packages/websocket/_core.py", line 487, in create_connection
    websock.connect(url, **options)
  File "/usr/lib/python3.6/site-packages/websocket/_core.py", line 211, in connect
    options.pop('socket', None))
  File "/usr/lib/python3.6/site-packages/websocket/_http.py", line 64, in connect
    hostname, port, is_secure, proxy)
  File "/usr/lib/python3.6/site-packages/websocket/_http.py", line 93, in _get_addrinfo_list
    hostname, port, 0, 0, socket.SOL_TCP)
  File "/usr/lib/python3.6/socket.py", line 745, in getaddrinfo
    for res in _socket.getaddrinfo(host, port, family, type, proto, flags):
socket.gaierror: [Errno -2] Name or service not known


--------------------
2018-01-22 17:07:51 - Exception on message: {'time': 1516639999, 'next': 1516640029}:
Traceback (most recent call last):
  File "heimdall.py", line 208, in <module>
    heimdall.disconnect()
  File "/home/struan/python/karelia/karelia.py", line 56, in connect
    "wss://euphoria.io/room/{}/ws".format(self.room))
  File "/usr/lib/python3.6/site-packages/websocket/_core.py", line 487, in create_connection
    websock.connect(url, **options)
  File "/usr/lib/python3.6/site-packages/websocket/_core.py", line 211, in connect
    options.pop('socket', None))
  File "/usr/lib/python3.6/site-packages/websocket/_http.py", line 64, in connect
    hostname, port, is_secure, proxy)
  File "/usr/lib/python3.6/site-packages/websocket/_http.py", line 93, in _get_addrinfo_list
    hostname, port, 0, 0, socket.SOL_TCP)
  File "/usr/lib/python3.6/socket.py", line 745, in getaddrinfo
    for res in _socket.getaddrinfo(host, port, family, type, proto, flags):
socket.gaierror: [Errno -2] Name or service not known


--------------------
2018-01-22 17:08:06 - Exception on message: {'time': 1516639999, 'next': 1516640029}:
Traceback (most recent call last):
  File "heimdall.py", line 208, in <module>
    heimdall.disconnect()
  File "/home/struan/python/karelia/karelia.py", line 56, in connect
    "wss://euphoria.io/room/{}/ws".format(self.room))
  File "/usr/lib/python3.6/site-packages/websocket/_core.py", line 487, in create_connection
    websock.connect(url, **options)
  File "/usr/lib/python3.6/site-packages/websocket/_core.py", line 211, in connect
    options.pop('socket', None))
  File "/usr/lib/python3.6/site-packages/websocket/_http.py", line 64, in connect
    hostname, port, is_secure, proxy)
  File "/usr/lib/python3.6/site-packages/websocket/_http.py", line 93, in _get_addrinfo_list
    hostname, port, 0, 0, socket.SOL_TCP)
  File "/usr/lib/python3.6/socket.py", line 745, in getaddrinfo
    for res in _socket.getaddrinfo(host, port, family, type, proto, flags):
socket.gaierror: [Errno -2] Name or service not known


--------------------
2018-01-22 17:08:21 - Exception on message: {'time': 1516639999, 'next': 1516640029}:
Traceback (most recent call last):
  File "heimdall.py", line 208, in <module>
    heimdall.disconnect()
  File "/home/struan/python/karelia/karelia.py", line 56, in connect
    "wss://euphoria.io/room/{}/ws".format(self.room))
  File "/usr/lib/python3.6/site-packages/websocket/_core.py", line 487, in create_connection
    websock.connect(url, **options)
  File "/usr/lib/python3.6/site-packages/websocket/_core.py", line 211, in connect
    options.pop('socket', None))
  File "/usr/lib/python3.6/site-packages/websocket/_http.py", line 64, in connect
    hostname, port, is_secure, proxy)
  File "/usr/lib/python3.6/site-packages/websocket/_http.py", line 93, in _get_addrinfo_list
    hostname, port, 0, 0, socket.SOL_TCP)
  File "/usr/lib/python3.6/socket.py", line 745, in getaddrinfo
    for res in _socket.getaddrinfo(host, port, family, type, proto, flags):
socket.gaierror: [Errno -2] Name or service not known


--------------------
2018-01-22 17:08:36 - Exception on message: {'time': 1516639999, 'next': 1516640029}:
Traceback (most recent call last):
  File "heimdall.py", line 208, in <module>
    heimdall.disconnect()
  File "/home/struan/python/karelia/karelia.py", line 56, in connect
    "wss://euphoria.io/room/{}/ws".format(self.room))
  File "/usr/lib/python3.6/site-packages/websocket/_core.py", line 487, in create_connection
    websock.connect(url, **options)
  File "/usr/lib/python3.6/site-packages/websocket/_core.py", line 211, in connect
    options.pop('socket', None))
  File "/usr/lib/python3.6/site-packages/websocket/_http.py", line 64, in connect
    hostname, port, is_secure, proxy)
  File "/usr/lib/python3.6/site-packages/websocket/_http.py", line 93, in _get_addrinfo_list
    hostname, port, 0, 0, socket.SOL_TCP)
  File "/usr/lib/python3.6/socket.py", line 745, in getaddrinfo
    for res in _socket.getaddrinfo(host, port, family, type, proto, flags):
socket.gaierror: [Errno -2] Name or service not known


--------------------
2018-01-22 17:08:51 - Exception on message: {'time': 1516639999, 'next': 1516640029}:
Traceback (most recent call last):
  File "heimdall.py", line 208, in <module>
    heimdall.disconnect()
  File "/home/struan/python/karelia/karelia.py", line 56, in connect
    "wss://euphoria.io/room/{}/ws".format(self.room))
  File "/usr/lib/python3.6/site-packages/websocket/_core.py", line 487, in create_connection
    websock.connect(url, **options)
  File "/usr/lib/python3.6/site-packages/websocket/_core.py", line 211, in connect
    options.pop('socket', None))
  File "/usr/lib/python3.6/site-packages/websocket/_http.py", line 64, in connect
    hostname, port, is_secure, proxy)
  File "/usr/lib/python3.6/site-packages/websocket/_http.py", line 93, in _get_addrinfo_list
    hostname, port, 0, 0, socket.SOL_TCP)
  File "/usr/lib/python3.6/socket.py", line 745, in getaddrinfo
    for res in _socket.getaddrinfo(host, port, family, type, proto, flags):
socket.gaierror: [Errno -2] Name or service not known


--------------------
2018-01-22 17:09:06 - Exception on message: {'time': 1516639999, 'next': 1516640029}:
Traceback (most recent call last):
  File "heimdall.py", line 208, in <module>
    heimdall.disconnect()
  File "/home/struan/python/karelia/karelia.py", line 56, in connect
    "wss://euphoria.io/room/{}/ws".format(self.room))
  File "/usr/lib/python3.6/site-packages/websocket/_core.py", line 487, in create_connection
    websock.connect(url, **options)
  File "/usr/lib/python3.6/site-packages/websocket/_core.py", line 211, in connect
    options.pop('socket', None))
  File "/usr/lib/python3.6/site-packages/websocket/_http.py", line 64, in connect
    hostname, port, is_secure, proxy)
  File "/usr/lib/python3.6/site-packages/websocket/_http.py", line 93, in _get_addrinfo_list
    hostname, port, 0, 0, socket.SOL_TCP)
  File "/usr/lib/python3.6/socket.py", line 745, in getaddrinfo
    for res in _socket.getaddrinfo(host, port, family, type, proto, flags):
socket.gaierror: [Errno -2] Name or service not known


--------------------
2018-01-22 17:09:21 - Exception on message: {'time': 1516639999, 'next': 1516640029}:
Traceback (most recent call last):
  File "heimdall.py", line 208, in <module>
    heimdall.disconnect()
  File "/home/struan/python/karelia/karelia.py", line 56, in connect
    "wss://euphoria.io/room/{}/ws".format(self.room))
  File "/usr/lib/python3.6/site-packages/websocket/_core.py", line 487, in create_connection
    websock.connect(url, **options)
  File "/usr/lib/python3.6/site-packages/websocket/_core.py", line 211, in connect
    options.pop('socket', None))
  File "/usr/lib/python3.6/site-packages/websocket/_http.py", line 64, in connect
    hostname, port, is_secure, proxy)
  File "/usr/lib/python3.6/site-packages/websocket/_http.py", line 93, in _get_addrinfo_list
    hostname, port, 0, 0, socket.SOL_TCP)
  File "/usr/lib/python3.6/socket.py", line 745, in getaddrinfo
    for res in _socket.getaddrinfo(host, port, family, type, proto, flags):
socket.gaierror: [Errno -2] Name or service not known


--------------------
2018-01-22 17:09:36 - Exception on message: {'time': 1516639999, 'next': 1516640029}:
Traceback (most recent call last):
  File "heimdall.py", line 208, in <module>
    heimdall.disconnect()
  File "/home/struan/python/karelia/karelia.py", line 56, in connect
    "wss://euphoria.io/room/{}/ws".format(self.room))
  File "/usr/lib/python3.6/site-packages/websocket/_core.py", line 487, in create_connection
    websock.connect(url, **options)
  File "/usr/lib/python3.6/site-packages/websocket/_core.py", line 211, in connect
    options.pop('socket', None))
  File "/usr/lib/python3.6/site-packages/websocket/_http.py", line 64, in connect
    hostname, port, is_secure, proxy)
  File "/usr/lib/python3.6/site-packages/websocket/_http.py", line 93, in _get_addrinfo_list
    hostname, port, 0, 0, socket.SOL_TCP)
  File "/usr/lib/python3.6/socket.py", line 745, in getaddrinfo
    for res in _socket.getaddrinfo(host, port, family, type, proto, flags):
socket.gaierror: [Errno -2] Name or service not known


--------------------
2018-01-22 17:09:51 - Exception on message: {'time': 1516639999, 'next': 1516640029}:
Traceback (most recent call last):
  File "heimdall.py", line 208, in <module>
    heimdall.disconnect()
  File "/home/struan/python/karelia/karelia.py", line 56, in connect
    "wss://euphoria.io/room/{}/ws".format(self.room))
  File "/usr/lib/python3.6/site-packages/websocket/_core.py", line 487, in create_connection
    websock.connect(url, **options)
  File "/usr/lib/python3.6/site-packages/websocket/_core.py", line 211, in connect
    options.pop('socket', None))
  File "/usr/lib/python3.6/site-packages/websocket/_http.py", line 64, in connect
    hostname, port, is_secure, proxy)
  File "/usr/lib/python3.6/site-packages/websocket/_http.py", line 93, in _get_addrinfo_list
    hostname, port, 0, 0, socket.SOL_TCP)
  File "/usr/lib/python3.6/socket.py", line 745, in getaddrinfo
    for res in _socket.getaddrinfo(host, port, family, type, proto, flags):
socket.gaierror: [Errno -2] Name or service not known


--------------------
2018-01-22 17:10:06 - Exception on message: {'time': 1516639999, 'next': 1516640029}:
Traceback (most recent call last):
  File "heimdall.py", line 208, in <module>
    heimdall.disconnect()
  File "/home/struan/python/karelia/karelia.py", line 56, in connect
    "wss://euphoria.io/room/{}/ws".format(self.room))
  File "/usr/lib/python3.6/site-packages/websocket/_core.py", line 487, in create_connection
    websock.connect(url, **options)
  File "/usr/lib/python3.6/site-packages/websocket/_core.py", line 211, in connect
    options.pop('socket', None))
  File "/usr/lib/python3.6/site-packages/websocket/_http.py", line 64, in connect
    hostname, port, is_secure, proxy)
  File "/usr/lib/python3.6/site-packages/websocket/_http.py", line 93, in _get_addrinfo_list
    hostname, port, 0, 0, socket.SOL_TCP)
  File "/usr/lib/python3.6/socket.py", line 745, in getaddrinfo
    for res in _socket.getaddrinfo(host, port, family, type, proto, flags):
socket.gaierror: [Errno -2] Name or service not known


--------------------
2018-01-22 17:10:21 - Exception on message: {'time': 1516639999, 'next': 1516640029}:
Traceback (most recent call last):
  File "heimdall.py", line 208, in <module>
    heimdall.disconnect()
  File "/home/struan/python/karelia/karelia.py", line 56, in connect
    "wss://euphoria.io/room/{}/ws".format(self.room))
  File "/usr/lib/python3.6/site-packages/websocket/_core.py", line 487, in create_connection
    websock.connect(url, **options)
  File "/usr/lib/python3.6/site-packages/websocket/_core.py", line 211, in connect
    options.pop('socket', None))
  File "/usr/lib/python3.6/site-packages/websocket/_http.py", line 64, in connect
    hostname, port, is_secure, proxy)
  File "/usr/lib/python3.6/site-packages/websocket/_http.py", line 93, in _get_addrinfo_list
    hostname, port, 0, 0, socket.SOL_TCP)
  File "/usr/lib/python3.6/socket.py", line 745, in getaddrinfo
    for res in _socket.getaddrinfo(host, port, family, type, proto, flags):
socket.gaierror: [Errno -2] Name or service not known


--------------------
2018-01-22 17:10:36 - Exception on message: {'time': 1516639999, 'next': 1516640029}:
Traceback (most recent call last):
  File "heimdall.py", line 208, in <module>
    heimdall.disconnect()
  File "/home/struan/python/karelia/karelia.py", line 56, in connect
    "wss://euphoria.io/room/{}/ws".format(self.room))
  File "/usr/lib/python3.6/site-packages/websocket/_core.py", line 487, in create_connection
    websock.connect(url, **options)
  File "/usr/lib/python3.6/site-packages/websocket/_core.py", line 211, in connect
    options.pop('socket', None))
  File "/usr/lib/python3.6/site-packages/websocket/_http.py", line 64, in connect
    hostname, port, is_secure, proxy)
  File "/usr/lib/python3.6/site-packages/websocket/_http.py", line 93, in _get_addrinfo_list
    hostname, port, 0, 0, socket.SOL_TCP)
  File "/usr/lib/python3.6/socket.py", line 745, in getaddrinfo
    for res in _socket.getaddrinfo(host, port, family, type, proto, flags):
socket.gaierror: [Errno -2] Name or service not known


--------------------
2018-01-22 17:10:51 - Exception on message: {'time': 1516639999, 'next': 1516640029}:
Traceback (most recent call last):
  File "heimdall.py", line 208, in <module>
    heimdall.disconnect()
  File "/home/struan/python/karelia/karelia.py", line 56, in connect
    "wss://euphoria.io/room/{}/ws".format(self.room))
  File "/usr/lib/python3.6/site-packages/websocket/_core.py", line 487, in create_connection
    websock.connect(url, **options)
  File "/usr/lib/python3.6/site-packages/websocket/_core.py", line 211, in connect
    options.pop('socket', None))
  File "/usr/lib/python3.6/site-packages/websocket/_http.py", line 64, in connect
    hostname, port, is_secure, proxy)
  File "/usr/lib/python3.6/site-packages/websocket/_http.py", line 93, in _get_addrinfo_list
    hostname, port, 0, 0, socket.SOL_TCP)
  File "/usr/lib/python3.6/socket.py", line 745, in getaddrinfo
    for res in _socket.getaddrinfo(host, port, family, type, proto, flags):
socket.gaierror: [Errno -2] Name or service not known


--------------------
2018-01-22 17:11:06 - Exception on message: {'time': 1516639999, 'next': 1516640029}:
Traceback (most recent call last):
  File "heimdall.py", line 208, in <module>
    heimdall.disconnect()
  File "/home/struan/python/karelia/karelia.py", line 56, in connect
    "wss://euphoria.io/room/{}/ws".format(self.room))
  File "/usr/lib/python3.6/site-packages/websocket/_core.py", line 487, in create_connection
    websock.connect(url, **options)
  File "/usr/lib/python3.6/site-packages/websocket/_core.py", line 211, in connect
    options.pop('socket', None))
  File "/usr/lib/python3.6/site-packages/websocket/_http.py", line 64, in connect
    hostname, port, is_secure, proxy)
  File "/usr/lib/python3.6/site-packages/websocket/_http.py", line 93, in _get_addrinfo_list
    hostname, port, 0, 0, socket.SOL_TCP)
  File "/usr/lib/python3.6/socket.py", line 745, in getaddrinfo
    for res in _socket.getaddrinfo(host, port, family, type, proto, flags):
socket.gaierror: [Errno -2] Name or service not known


--------------------
2018-01-22 17:11:21 - Exception on message: {'time': 1516639999, 'next': 1516640029}:
Traceback (most recent call last):
  File "heimdall.py", line 208, in <module>
    heimdall.disconnect()
  File "/home/struan/python/karelia/karelia.py", line 56, in connect
    "wss://euphoria.io/room/{}/ws".format(self.room))
  File "/usr/lib/python3.6/site-packages/websocket/_core.py", line 487, in create_connection
    websock.connect(url, **options)
  File "/usr/lib/python3.6/site-packages/websocket/_core.py", line 211, in connect
    options.pop('socket', None))
  File "/usr/lib/python3.6/site-packages/websocket/_http.py", line 64, in connect
    hostname, port, is_secure, proxy)
  File "/usr/lib/python3.6/site-packages/websocket/_http.py", line 93, in _get_addrinfo_list
    hostname, port, 0, 0, socket.SOL_TCP)
  File "/usr/lib/python3.6/socket.py", line 745, in getaddrinfo
    for res in _socket.getaddrinfo(host, port, family, type, proto, flags):
socket.gaierror: [Errno -2] Name or service not known


--------------------
2018-01-22 17:11:36 - Exception on message: {'time': 1516639999, 'next': 1516640029}:
Traceback (most recent call last):
  File "heimdall.py", line 208, in <module>
    heimdall.disconnect()
  File "/home/struan/python/karelia/karelia.py", line 56, in connect
    "wss://euphoria.io/room/{}/ws".format(self.room))
  File "/usr/lib/python3.6/site-packages/websocket/_core.py", line 487, in create_connection
    websock.connect(url, **options)
  File "/usr/lib/python3.6/site-packages/websocket/_core.py", line 211, in connect
    options.pop('socket', None))
  File "/usr/lib/python3.6/site-packages/websocket/_http.py", line 64, in connect
    hostname, port, is_secure, proxy)
  File "/usr/lib/python3.6/site-packages/websocket/_http.py", line 93, in _get_addrinfo_list
    hostname, port, 0, 0, socket.SOL_TCP)
  File "/usr/lib/python3.6/socket.py", line 745, in getaddrinfo
    for res in _socket.getaddrinfo(host, port, family, type, proto, flags):
socket.gaierror: [Errno -2] Name or service not known


--------------------
2018-01-22 17:11:51 - Exception on message: {'time': 1516639999, 'next': 1516640029}:
Traceback (most recent call last):
  File "heimdall.py", line 208, in <module>
    heimdall.disconnect()
  File "/home/struan/python/karelia/karelia.py", line 56, in connect
    "wss://euphoria.io/room/{}/ws".format(self.room))
  File "/usr/lib/python3.6/site-packages/websocket/_core.py", line 487, in create_connection
    websock.connect(url, **options)
  File "/usr/lib/python3.6/site-packages/websocket/_core.py", line 211, in connect
    options.pop('socket', None))
  File "/usr/lib/python3.6/site-packages/websocket/_http.py", line 64, in connect
    hostname, port, is_secure, proxy)
  File "/usr/lib/python3.6/site-packages/websocket/_http.py", line 93, in _get_addrinfo_list
    hostname, port, 0, 0, socket.SOL_TCP)
  File "/usr/lib/python3.6/socket.py", line 745, in getaddrinfo
    for res in _socket.getaddrinfo(host, port, family, type, proto, flags):
socket.gaierror: [Errno -2] Name or service not known


--------------------
2018-01-22 17:12:06 - Exception on message: {'time': 1516639999, 'next': 1516640029}:
Traceback (most recent call last):
  File "heimdall.py", line 208, in <module>
    heimdall.disconnect()
  File "/home/struan/python/karelia/karelia.py", line 56, in connect
    "wss://euphoria.io/room/{}/ws".format(self.room))
  File "/usr/lib/python3.6/site-packages/websocket/_core.py", line 487, in create_connection
    websock.connect(url, **options)
  File "/usr/lib/python3.6/site-packages/websocket/_core.py", line 211, in connect
    options.pop('socket', None))
  File "/usr/lib/python3.6/site-packages/websocket/_http.py", line 64, in connect
    hostname, port, is_secure, proxy)
  File "/usr/lib/python3.6/site-packages/websocket/_http.py", line 93, in _get_addrinfo_list
    hostname, port, 0, 0, socket.SOL_TCP)
  File "/usr/lib/python3.6/socket.py", line 745, in getaddrinfo
    for res in _socket.getaddrinfo(host, port, family, type, proto, flags):
socket.gaierror: [Errno -2] Name or service not known


--------------------
2018-01-22 17:12:21 - Exception on message: {'time': 1516639999, 'next': 1516640029}:
Traceback (most recent call last):
  File "heimdall.py", line 208, in <module>
    heimdall.disconnect()
  File "/home/struan/python/karelia/karelia.py", line 56, in connect
    "wss://euphoria.io/room/{}/ws".format(self.room))
  File "/usr/lib/python3.6/site-packages/websocket/_core.py", line 487, in create_connection
    websock.connect(url, **options)
  File "/usr/lib/python3.6/site-packages/websocket/_core.py", line 211, in connect
    options.pop('socket', None))
  File "/usr/lib/python3.6/site-packages/websocket/_http.py", line 64, in connect
    hostname, port, is_secure, proxy)
  File "/usr/lib/python3.6/site-packages/websocket/_http.py", line 93, in _get_addrinfo_list
    hostname, port, 0, 0, socket.SOL_TCP)
  File "/usr/lib/python3.6/socket.py", line 745, in getaddrinfo
    for res in _socket.getaddrinfo(host, port, family, type, proto, flags):
socket.gaierror: [Errno -2] Name or service not known


--------------------
2018-01-22 17:12:36 - Exception on message: {'time': 1516639999, 'next': 1516640029}:
Traceback (most recent call last):
  File "heimdall.py", line 208, in <module>
    heimdall.disconnect()
  File "/home/struan/python/karelia/karelia.py", line 56, in connect
    "wss://euphoria.io/room/{}/ws".format(self.room))
  File "/usr/lib/python3.6/site-packages/websocket/_core.py", line 487, in create_connection
    websock.connect(url, **options)
  File "/usr/lib/python3.6/site-packages/websocket/_core.py", line 211, in connect
    options.pop('socket', None))
  File "/usr/lib/python3.6/site-packages/websocket/_http.py", line 64, in connect
    hostname, port, is_secure, proxy)
  File "/usr/lib/python3.6/site-packages/websocket/_http.py", line 93, in _get_addrinfo_list
    hostname, port, 0, 0, socket.SOL_TCP)
  File "/usr/lib/python3.6/socket.py", line 745, in getaddrinfo
    for res in _socket.getaddrinfo(host, port, family, type, proto, flags):
socket.gaierror: [Errno -2] Name or service not known


--------------------
2018-01-22 17:12:51 - Exception on message: {'time': 1516639999, 'next': 1516640029}:
Traceback (most recent call last):
  File "heimdall.py", line 208, in <module>
    heimdall.disconnect()
  File "/home/struan/python/karelia/karelia.py", line 56, in connect
    "wss://euphoria.io/room/{}/ws".format(self.room))
  File "/usr/lib/python3.6/site-packages/websocket/_core.py", line 487, in create_connection
    websock.connect(url, **options)
  File "/usr/lib/python3.6/site-packages/websocket/_core.py", line 211, in connect
    options.pop('socket', None))
  File "/usr/lib/python3.6/site-packages/websocket/_http.py", line 64, in connect
    hostname, port, is_secure, proxy)
  File "/usr/lib/python3.6/site-packages/websocket/_http.py", line 93, in _get_addrinfo_list
    hostname, port, 0, 0, socket.SOL_TCP)
  File "/usr/lib/python3.6/socket.py", line 745, in getaddrinfo
    for res in _socket.getaddrinfo(host, port, family, type, proto, flags):
socket.gaierror: [Errno -2] Name or service not known


--------------------
2018-01-22 17:13:06 - Exception on message: {'time': 1516639999, 'next': 1516640029}:
Traceback (most recent call last):
  File "heimdall.py", line 208, in <module>
    heimdall.disconnect()
  File "/home/struan/python/karelia/karelia.py", line 56, in connect
    "wss://euphoria.io/room/{}/ws".format(self.room))
  File "/usr/lib/python3.6/site-packages/websocket/_core.py", line 487, in create_connection
    websock.connect(url, **options)
  File "/usr/lib/python3.6/site-packages/websocket/_core.py", line 211, in connect
    options.pop('socket', None))
  File "/usr/lib/python3.6/site-packages/websocket/_http.py", line 64, in connect
    hostname, port, is_secure, proxy)
  File "/usr/lib/python3.6/site-packages/websocket/_http.py", line 93, in _get_addrinfo_list
    hostname, port, 0, 0, socket.SOL_TCP)
  File "/usr/lib/python3.6/socket.py", line 745, in getaddrinfo
    for res in _socket.getaddrinfo(host, port, family, type, proto, flags):
socket.gaierror: [Errno -2] Name or service not known


--------------------
2018-01-22 17:13:21 - Exception on message: {'time': 1516639999, 'next': 1516640029}:
Traceback (most recent call last):
  File "heimdall.py", line 208, in <module>
    heimdall.disconnect()
  File "/home/struan/python/karelia/karelia.py", line 56, in connect
    "wss://euphoria.io/room/{}/ws".format(self.room))
  File "/usr/lib/python3.6/site-packages/websocket/_core.py", line 487, in create_connection
    websock.connect(url, **options)
  File "/usr/lib/python3.6/site-packages/websocket/_core.py", line 211, in connect
    options.pop('socket', None))
  File "/usr/lib/python3.6/site-packages/websocket/_http.py", line 64, in connect
    hostname, port, is_secure, proxy)
  File "/usr/lib/python3.6/site-packages/websocket/_http.py", line 93, in _get_addrinfo_list
    hostname, port, 0, 0, socket.SOL_TCP)
  File "/usr/lib/python3.6/socket.py", line 745, in getaddrinfo
    for res in _socket.getaddrinfo(host, port, family, type, proto, flags):
socket.gaierror: [Errno -2] Name or service not known


--------------------
2018-01-22 17:13:36 - Exception on message: {'time': 1516639999, 'next': 1516640029}:
Traceback (most recent call last):
  File "heimdall.py", line 208, in <module>
    heimdall.disconnect()
  File "/home/struan/python/karelia/karelia.py", line 56, in connect
    "wss://euphoria.io/room/{}/ws".format(self.room))
  File "/usr/lib/python3.6/site-packages/websocket/_core.py", line 487, in create_connection
    websock.connect(url, **options)
  File "/usr/lib/python3.6/site-packages/websocket/_core.py", line 211, in connect
    options.pop('socket', None))
  File "/usr/lib/python3.6/site-packages/websocket/_http.py", line 64, in connect
    hostname, port, is_secure, proxy)
  File "/usr/lib/python3.6/site-packages/websocket/_http.py", line 93, in _get_addrinfo_list
    hostname, port, 0, 0, socket.SOL_TCP)
  File "/usr/lib/python3.6/socket.py", line 745, in getaddrinfo
    for res in _socket.getaddrinfo(host, port, family, type, proto, flags):
socket.gaierror: [Errno -2] Name or service not known


--------------------
2018-01-22 17:13:51 - Exception on message: {'time': 1516639999, 'next': 1516640029}:
Traceback (most recent call last):
  File "heimdall.py", line 208, in <module>
    heimdall.disconnect()
  File "/home/struan/python/karelia/karelia.py", line 56, in connect
    "wss://euphoria.io/room/{}/ws".format(self.room))
  File "/usr/lib/python3.6/site-packages/websocket/_core.py", line 487, in create_connection
    websock.connect(url, **options)
  File "/usr/lib/python3.6/site-packages/websocket/_core.py", line 211, in connect
    options.pop('socket', None))
  File "/usr/lib/python3.6/site-packages/websocket/_http.py", line 64, in connect
    hostname, port, is_secure, proxy)
  File "/usr/lib/python3.6/site-packages/websocket/_http.py", line 93, in _get_addrinfo_list
    hostname, port, 0, 0, socket.SOL_TCP)
  File "/usr/lib/python3.6/socket.py", line 745, in getaddrinfo
    for res in _socket.getaddrinfo(host, port, family, type, proto, flags):
socket.gaierror: [Errno -2] Name or service not known


--------------------
2018-01-22 17:13:56 - Exception on message: {'time': 1516639999, 'next': 1516640029}:
Traceback (most recent call last):
  File "heimdall.py", line 208, in <module>
    heimdall.disconnect()
  File "/home/struan/python/karelia/karelia.py", line 56, in connect
    "wss://euphoria.io/room/{}/ws".format(self.room))
  File "/usr/lib/python3.6/site-packages/websocket/_core.py", line 487, in create_connection
    websock.connect(url, **options)
  File "/usr/lib/python3.6/site-packages/websocket/_core.py", line 211, in connect
    options.pop('socket', None))
  File "/usr/lib/python3.6/site-packages/websocket/_http.py", line 64, in connect
    hostname, port, is_secure, proxy)
  File "/usr/lib/python3.6/site-packages/websocket/_http.py", line 93, in _get_addrinfo_list
    hostname, port, 0, 0, socket.SOL_TCP)
  File "/usr/lib/python3.6/socket.py", line 745, in getaddrinfo
    for res in _socket.getaddrinfo(host, port, family, type, proto, flags):
socket.gaierror: [Errno -2] Name or service not known


--------------------
2018-01-22 17:14:01 - Exception on message: {'time': 1516639999, 'next': 1516640029}:
Traceback (most recent call last):
  File "heimdall.py", line 208, in <module>
    heimdall.disconnect()
  File "/home/struan/python/karelia/karelia.py", line 56, in connect
    "wss://euphoria.io/room/{}/ws".format(self.room))
  File "/usr/lib/python3.6/site-packages/websocket/_core.py", line 487, in create_connection
    websock.connect(url, **options)
  File "/usr/lib/python3.6/site-packages/websocket/_core.py", line 211, in connect
    options.pop('socket', None))
  File "/usr/lib/python3.6/site-packages/websocket/_http.py", line 64, in connect
    hostname, port, is_secure, proxy)
  File "/usr/lib/python3.6/site-packages/websocket/_http.py", line 93, in _get_addrinfo_list
    hostname, port, 0, 0, socket.SOL_TCP)
  File "/usr/lib/python3.6/socket.py", line 745, in getaddrinfo
    for res in _socket.getaddrinfo(host, port, family, type, proto, flags):
socket.gaierror: [Errno -2] Name or service not known


--------------------
2018-01-22 17:14:06 - Exception on message: {'time': 1516639999, 'next': 1516640029}:
Traceback (most recent call last):
  File "heimdall.py", line 208, in <module>
    heimdall.disconnect()
  File "/home/struan/python/karelia/karelia.py", line 56, in connect
    "wss://euphoria.io/room/{}/ws".format(self.room))
  File "/usr/lib/python3.6/site-packages/websocket/_core.py", line 487, in create_connection
    websock.connect(url, **options)
  File "/usr/lib/python3.6/site-packages/websocket/_core.py", line 211, in connect
    options.pop('socket', None))
  File "/usr/lib/python3.6/site-packages/websocket/_http.py", line 64, in connect
    hostname, port, is_secure, proxy)
  File "/usr/lib/python3.6/site-packages/websocket/_http.py", line 93, in _get_addrinfo_list
    hostname, port, 0, 0, socket.SOL_TCP)
  File "/usr/lib/python3.6/socket.py", line 745, in getaddrinfo
    for res in _socket.getaddrinfo(host, port, family, type, proto, flags):
socket.gaierror: [Errno -2] Name or service not known


--------------------
2018-01-22 17:14:11 - Exception on message: {'time': 1516639999, 'next': 1516640029}:
Traceback (most recent call last):
  File "heimdall.py", line 208, in <module>
    heimdall.disconnect()
  File "/home/struan/python/karelia/karelia.py", line 56, in connect
    "wss://euphoria.io/room/{}/ws".format(self.room))
  File "/usr/lib/python3.6/site-packages/websocket/_core.py", line 487, in create_connection
    websock.connect(url, **options)
  File "/usr/lib/python3.6/site-packages/websocket/_core.py", line 211, in connect
    options.pop('socket', None))
  File "/usr/lib/python3.6/site-packages/websocket/_http.py", line 64, in connect
    hostname, port, is_secure, proxy)
  File "/usr/lib/python3.6/site-packages/websocket/_http.py", line 93, in _get_addrinfo_list
    hostname, port, 0, 0, socket.SOL_TCP)
  File "/usr/lib/python3.6/socket.py", line 745, in getaddrinfo
    for res in _socket.getaddrinfo(host, port, family, type, proto, flags):
socket.gaierror: [Errno -2] Name or service not known


--------------------
2018-01-22 17:14:16 - Exception on message: {'time': 1516639999, 'next': 1516640029}:
Traceback (most recent call last):
  File "heimdall.py", line 208, in <module>
    heimdall.disconnect()
  File "/home/struan/python/karelia/karelia.py", line 56, in connect
    "wss://euphoria.io/room/{}/ws".format(self.room))
  File "/usr/lib/python3.6/site-packages/websocket/_core.py", line 487, in create_connection
    websock.connect(url, **options)
  File "/usr/lib/python3.6/site-packages/websocket/_core.py", line 211, in connect
    options.pop('socket', None))
  File "/usr/lib/python3.6/site-packages/websocket/_http.py", line 64, in connect
    hostname, port, is_secure, proxy)
  File "/usr/lib/python3.6/site-packages/websocket/_http.py", line 93, in _get_addrinfo_list
    hostname, port, 0, 0, socket.SOL_TCP)
  File "/usr/lib/python3.6/socket.py", line 745, in getaddrinfo
    for res in _socket.getaddrinfo(host, port, family, type, proto, flags):
socket.gaierror: [Errno -2] Name or service not known


--------------------
2018-01-22 17:14:21 - Exception on message: {'time': 1516639999, 'next': 1516640029}:
Traceback (most recent call last):
  File "heimdall.py", line 208, in <module>
    heimdall.disconnect()
  File "/home/struan/python/karelia/karelia.py", line 56, in connect
    "wss://euphoria.io/room/{}/ws".format(self.room))
  File "/usr/lib/python3.6/site-packages/websocket/_core.py", line 487, in create_connection
    websock.connect(url, **options)
  File "/usr/lib/python3.6/site-packages/websocket/_core.py", line 211, in connect
    options.pop('socket', None))
  File "/usr/lib/python3.6/site-packages/websocket/_http.py", line 64, in connect
    hostname, port, is_secure, proxy)
  File "/usr/lib/python3.6/site-packages/websocket/_http.py", line 93, in _get_addrinfo_list
    hostname, port, 0, 0, socket.SOL_TCP)
  File "/usr/lib/python3.6/socket.py", line 745, in getaddrinfo
    for res in _socket.getaddrinfo(host, port, family, type, proto, flags):
socket.gaierror: [Errno -2] Name or service not known


--------------------
2018-01-23 00:51:29 - Exception on message: {'time': 1516668627, 'next': 1516668657}:
Traceback (most recent call last):
  File "/home/struan/python/karelia/karelia.py", line 177, in parse
    incoming = self.conn.recv()
  File "/usr/lib/python3.6/site-packages/websocket/_core.py", line 293, in recv
    opcode, data = self.recv_data()
  File "/usr/lib/python3.6/site-packages/websocket/_core.py", line 310, in recv_data
    opcode, frame = self.recv_data_frame(control_frame)
  File "/usr/lib/python3.6/site-packages/websocket/_core.py", line 323, in recv_data_frame
    frame = self.recv_frame()
  File "/usr/lib/python3.6/site-packages/websocket/_core.py", line 357, in recv_frame
    return self.frame_buffer.recv_frame()
  File "/usr/lib/python3.6/site-packages/websocket/_abnf.py", line 336, in recv_frame
    self.recv_header()
  File "/usr/lib/python3.6/site-packages/websocket/_abnf.py", line 286, in recv_header
    header = self.recv_strict(2)
  File "/usr/lib/python3.6/site-packages/websocket/_abnf.py", line 371, in recv_strict
    bytes_ = self.recv(min(16384, shortage))
  File "/usr/lib/python3.6/site-packages/websocket/_core.py", line 427, in _recv
    return recv(self.sock, bufsize)
  File "/usr/lib/python3.6/site-packages/websocket/_socket.py", line 80, in recv
    bytes_ = sock.recv(bufsize)
  File "/usr/lib/python3.6/ssl.py", line 994, in recv
    return self.read(buflen)
  File "/usr/lib/python3.6/ssl.py", line 871, in read
    return self._sslobj.read(len, buffer)
  File "/usr/lib/python3.6/ssl.py", line 633, in read
    v = self._sslobj.read(len)
TimeoutError: [Errno 110] Connection timed out

During handling of the above exception, another exception occurred:

Traceback (most recent call last):
  File "heimdall.py", line 213, in <module>
    conn = sqlite3.connect('logs.db')
  File "/home/struan/python/karelia/karelia.py", line 239, in parse
    {'message': 'There was an error parsing the message', 'error': e})
karelia.KareliaException: {'message': 'There was an error parsing the message', 'error': TimeoutError(110, 'Connection timed out')}


--------------------
2018-01-23 02:17:04 - Exception on message: {'time': 1516673762, 'next': 1516673792}:
Traceback (most recent call last):
  File "/home/struan/python/karelia/karelia.py", line 177, in parse
    incoming = self.conn.recv()
  File "/usr/lib/python3.6/site-packages/websocket/_core.py", line 293, in recv
    opcode, data = self.recv_data()
  File "/usr/lib/python3.6/site-packages/websocket/_core.py", line 310, in recv_data
    opcode, frame = self.recv_data_frame(control_frame)
  File "/usr/lib/python3.6/site-packages/websocket/_core.py", line 323, in recv_data_frame
    frame = self.recv_frame()
  File "/usr/lib/python3.6/site-packages/websocket/_core.py", line 357, in recv_frame
    return self.frame_buffer.recv_frame()
  File "/usr/lib/python3.6/site-packages/websocket/_abnf.py", line 336, in recv_frame
    self.recv_header()
  File "/usr/lib/python3.6/site-packages/websocket/_abnf.py", line 286, in recv_header
    header = self.recv_strict(2)
  File "/usr/lib/python3.6/site-packages/websocket/_abnf.py", line 371, in recv_strict
    bytes_ = self.recv(min(16384, shortage))
  File "/usr/lib/python3.6/site-packages/websocket/_core.py", line 427, in _recv
    return recv(self.sock, bufsize)
  File "/usr/lib/python3.6/site-packages/websocket/_socket.py", line 80, in recv
    bytes_ = sock.recv(bufsize)
  File "/usr/lib/python3.6/ssl.py", line 994, in recv
    return self.read(buflen)
  File "/usr/lib/python3.6/ssl.py", line 871, in read
    return self._sslobj.read(len, buffer)
  File "/usr/lib/python3.6/ssl.py", line 633, in read
    v = self._sslobj.read(len)
TimeoutError: [Errno 110] Connection timed out

During handling of the above exception, another exception occurred:

Traceback (most recent call last):
  File "heimdall.py", line 213, in <module>
    conn = sqlite3.connect('logs.db')
  File "/home/struan/python/karelia/karelia.py", line 239, in parse
    {'message': 'There was an error parsing the message', 'error': e})
karelia.KareliaException: {'message': 'There was an error parsing the message', 'error': TimeoutError(110, 'Connection timed out')}


--------------------
2018-01-24 02:51:01 - Exception on message: {'time': 1516762247, 'next': 1516762277}:
Traceback (most recent call last):
  File "/home/struan/python/karelia/karelia.py", line 177, in parse
    incoming = self.conn.recv()
  File "/usr/lib/python3.6/site-packages/websocket/_core.py", line 293, in recv
    opcode, data = self.recv_data()
  File "/usr/lib/python3.6/site-packages/websocket/_core.py", line 310, in recv_data
    opcode, frame = self.recv_data_frame(control_frame)
  File "/usr/lib/python3.6/site-packages/websocket/_core.py", line 323, in recv_data_frame
    frame = self.recv_frame()
  File "/usr/lib/python3.6/site-packages/websocket/_core.py", line 357, in recv_frame
    return self.frame_buffer.recv_frame()
  File "/usr/lib/python3.6/site-packages/websocket/_abnf.py", line 336, in recv_frame
    self.recv_header()
  File "/usr/lib/python3.6/site-packages/websocket/_abnf.py", line 286, in recv_header
    header = self.recv_strict(2)
  File "/usr/lib/python3.6/site-packages/websocket/_abnf.py", line 371, in recv_strict
    bytes_ = self.recv(min(16384, shortage))
  File "/usr/lib/python3.6/site-packages/websocket/_core.py", line 427, in _recv
    return recv(self.sock, bufsize)
  File "/usr/lib/python3.6/site-packages/websocket/_socket.py", line 93, in recv
    "Connection is already closed.")
websocket._exceptions.WebSocketConnectionClosedException: Connection is already closed.

During handling of the above exception, another exception occurred:

Traceback (most recent call last):
  File "heimdall.py", line 213, in <module>
    conn = sqlite3.connect('logs.db')
  File "/home/struan/python/karelia/karelia.py", line 239, in parse
    {'message': 'There was an error parsing the message', 'error': e})
karelia.KareliaException: {'message': 'There was an error parsing the message', 'error': WebSocketConnectionClosedException('Connection is already closed.',)}


--------------------
2018-01-26 15:46:49 - Exception on message: {'type': 'partition', 'server_id': 'heim.1', 'server_era': '0363gb00e2dq8'}:
Traceback (most recent call last):
  File "/home/struan/python/karelia/karelia.py", line 177, in parse
    incoming = self.conn.recv()
  File "/usr/lib/python3.6/site-packages/websocket/_core.py", line 293, in recv
    opcode, data = self.recv_data()
  File "/usr/lib/python3.6/site-packages/websocket/_core.py", line 310, in recv_data
    opcode, frame = self.recv_data_frame(control_frame)
  File "/usr/lib/python3.6/site-packages/websocket/_core.py", line 323, in recv_data_frame
    frame = self.recv_frame()
  File "/usr/lib/python3.6/site-packages/websocket/_core.py", line 357, in recv_frame
    return self.frame_buffer.recv_frame()
  File "/usr/lib/python3.6/site-packages/websocket/_abnf.py", line 336, in recv_frame
    self.recv_header()
  File "/usr/lib/python3.6/site-packages/websocket/_abnf.py", line 286, in recv_header
    header = self.recv_strict(2)
  File "/usr/lib/python3.6/site-packages/websocket/_abnf.py", line 371, in recv_strict
    bytes_ = self.recv(min(16384, shortage))
  File "/usr/lib/python3.6/site-packages/websocket/_core.py", line 427, in _recv
    return recv(self.sock, bufsize)
  File "/usr/lib/python3.6/site-packages/websocket/_socket.py", line 93, in recv
    "Connection is already closed.")
websocket._exceptions.WebSocketConnectionClosedException: Connection is already closed.

During handling of the above exception, another exception occurred:

Traceback (most recent call last):
  File "heimdall.py", line 213, in <module>
    conn = sqlite3.connect('logs.db')
  File "/home/struan/python/karelia/karelia.py", line 239, in parse
    {'message': 'There was an error parsing the message', 'error': e})
karelia.KareliaException: {'message': 'There was an error parsing the message', 'error': WebSocketConnectionClosedException('Connection is already closed.',)}


--------------------
2018-01-26 15:46:55 - Exception on message: {'type': 'partition', 'server_id': 'heim.1', 'server_era': '0363gb00e2dq8'}:
Traceback (most recent call last):
  File "heimdall.py", line 208, in <module>
    heimdall.disconnect()
  File "/home/struan/python/karelia/karelia.py", line 56, in connect
    "wss://euphoria.io/room/{}/ws".format(self.room))
  File "/usr/lib/python3.6/site-packages/websocket/_core.py", line 487, in create_connection
    websock.connect(url, **options)
  File "/usr/lib/python3.6/site-packages/websocket/_core.py", line 214, in connect
    self.handshake_response = handshake(self.sock, *addrs, **options)
  File "/usr/lib/python3.6/site-packages/websocket/_handshake.py", line 65, in handshake
    status, resp = _get_resp_headers(sock)
  File "/usr/lib/python3.6/site-packages/websocket/_handshake.py", line 122, in _get_resp_headers
    raise WebSocketBadStatusException("Handshake status %d", status)
websocket._exceptions.WebSocketBadStatusException: Handshake status 503


--------------------
2018-01-26 15:47:01 - Exception on message: {'type': 'partition', 'server_id': 'heim.1', 'server_era': '0363gb00e2dq8'}:
Traceback (most recent call last):
  File "heimdall.py", line 208, in <module>
    heimdall.disconnect()
  File "/home/struan/python/karelia/karelia.py", line 56, in connect
    "wss://euphoria.io/room/{}/ws".format(self.room))
  File "/usr/lib/python3.6/site-packages/websocket/_core.py", line 487, in create_connection
    websock.connect(url, **options)
  File "/usr/lib/python3.6/site-packages/websocket/_core.py", line 214, in connect
    self.handshake_response = handshake(self.sock, *addrs, **options)
  File "/usr/lib/python3.6/site-packages/websocket/_handshake.py", line 65, in handshake
    status, resp = _get_resp_headers(sock)
  File "/usr/lib/python3.6/site-packages/websocket/_handshake.py", line 122, in _get_resp_headers
    raise WebSocketBadStatusException("Handshake status %d", status)
websocket._exceptions.WebSocketBadStatusException: Handshake status 503


--------------------
2018-01-26 15:47:07 - Exception on message: {'type': 'partition', 'server_id': 'heim.1', 'server_era': '0363gb00e2dq8'}:
Traceback (most recent call last):
  File "heimdall.py", line 208, in <module>
    heimdall.disconnect()
  File "/home/struan/python/karelia/karelia.py", line 56, in connect
    "wss://euphoria.io/room/{}/ws".format(self.room))
  File "/usr/lib/python3.6/site-packages/websocket/_core.py", line 487, in create_connection
    websock.connect(url, **options)
  File "/usr/lib/python3.6/site-packages/websocket/_core.py", line 214, in connect
    self.handshake_response = handshake(self.sock, *addrs, **options)
  File "/usr/lib/python3.6/site-packages/websocket/_handshake.py", line 65, in handshake
    status, resp = _get_resp_headers(sock)
  File "/usr/lib/python3.6/site-packages/websocket/_handshake.py", line 122, in _get_resp_headers
    raise WebSocketBadStatusException("Handshake status %d", status)
websocket._exceptions.WebSocketBadStatusException: Handshake status 503


--------------------
2018-01-26 15:47:13 - Exception on message: {'type': 'partition', 'server_id': 'heim.1', 'server_era': '0363gb00e2dq8'}:
Traceback (most recent call last):
  File "heimdall.py", line 208, in <module>
    heimdall.disconnect()
  File "/home/struan/python/karelia/karelia.py", line 56, in connect
    "wss://euphoria.io/room/{}/ws".format(self.room))
  File "/usr/lib/python3.6/site-packages/websocket/_core.py", line 487, in create_connection
    websock.connect(url, **options)
  File "/usr/lib/python3.6/site-packages/websocket/_core.py", line 214, in connect
    self.handshake_response = handshake(self.sock, *addrs, **options)
  File "/usr/lib/python3.6/site-packages/websocket/_handshake.py", line 65, in handshake
    status, resp = _get_resp_headers(sock)
  File "/usr/lib/python3.6/site-packages/websocket/_handshake.py", line 122, in _get_resp_headers
    raise WebSocketBadStatusException("Handshake status %d", status)
websocket._exceptions.WebSocketBadStatusException: Handshake status 503


--------------------
2018-01-26 15:47:18 - Exception on message: {'type': 'partition', 'server_id': 'heim.1', 'server_era': '0363gb00e2dq8'}:
Traceback (most recent call last):
  File "heimdall.py", line 208, in <module>
    heimdall.disconnect()
  File "/home/struan/python/karelia/karelia.py", line 56, in connect
    "wss://euphoria.io/room/{}/ws".format(self.room))
  File "/usr/lib/python3.6/site-packages/websocket/_core.py", line 487, in create_connection
    websock.connect(url, **options)
  File "/usr/lib/python3.6/site-packages/websocket/_core.py", line 214, in connect
    self.handshake_response = handshake(self.sock, *addrs, **options)
  File "/usr/lib/python3.6/site-packages/websocket/_handshake.py", line 65, in handshake
    status, resp = _get_resp_headers(sock)
  File "/usr/lib/python3.6/site-packages/websocket/_handshake.py", line 122, in _get_resp_headers
    raise WebSocketBadStatusException("Handshake status %d", status)
websocket._exceptions.WebSocketBadStatusException: Handshake status 503


--------------------
2018-01-26 15:47:24 - Exception on message: {'type': 'partition', 'server_id': 'heim.1', 'server_era': '0363gb00e2dq8'}:
Traceback (most recent call last):
  File "heimdall.py", line 208, in <module>
    heimdall.disconnect()
  File "/home/struan/python/karelia/karelia.py", line 56, in connect
    "wss://euphoria.io/room/{}/ws".format(self.room))
  File "/usr/lib/python3.6/site-packages/websocket/_core.py", line 487, in create_connection
    websock.connect(url, **options)
  File "/usr/lib/python3.6/site-packages/websocket/_core.py", line 214, in connect
    self.handshake_response = handshake(self.sock, *addrs, **options)
  File "/usr/lib/python3.6/site-packages/websocket/_handshake.py", line 65, in handshake
    status, resp = _get_resp_headers(sock)
  File "/usr/lib/python3.6/site-packages/websocket/_handshake.py", line 122, in _get_resp_headers
    raise WebSocketBadStatusException("Handshake status %d", status)
websocket._exceptions.WebSocketBadStatusException: Handshake status 503


--------------------
2018-01-26 15:47:30 - Exception on message: {'type': 'partition', 'server_id': 'heim.1', 'server_era': '0363gb00e2dq8'}:
Traceback (most recent call last):
  File "heimdall.py", line 208, in <module>
    heimdall.disconnect()
  File "/home/struan/python/karelia/karelia.py", line 56, in connect
    "wss://euphoria.io/room/{}/ws".format(self.room))
  File "/usr/lib/python3.6/site-packages/websocket/_core.py", line 487, in create_connection
    websock.connect(url, **options)
  File "/usr/lib/python3.6/site-packages/websocket/_core.py", line 214, in connect
    self.handshake_response = handshake(self.sock, *addrs, **options)
  File "/usr/lib/python3.6/site-packages/websocket/_handshake.py", line 65, in handshake
    status, resp = _get_resp_headers(sock)
  File "/usr/lib/python3.6/site-packages/websocket/_handshake.py", line 122, in _get_resp_headers
    raise WebSocketBadStatusException("Handshake status %d", status)
websocket._exceptions.WebSocketBadStatusException: Handshake status 503


--------------------
2018-01-26 15:47:35 - Exception on message: {'type': 'partition', 'server_id': 'heim.1', 'server_era': '0363gb00e2dq8'}:
Traceback (most recent call last):
  File "heimdall.py", line 208, in <module>
    heimdall.disconnect()
  File "/home/struan/python/karelia/karelia.py", line 56, in connect
    "wss://euphoria.io/room/{}/ws".format(self.room))
  File "/usr/lib/python3.6/site-packages/websocket/_core.py", line 487, in create_connection
    websock.connect(url, **options)
  File "/usr/lib/python3.6/site-packages/websocket/_core.py", line 214, in connect
    self.handshake_response = handshake(self.sock, *addrs, **options)
  File "/usr/lib/python3.6/site-packages/websocket/_handshake.py", line 65, in handshake
    status, resp = _get_resp_headers(sock)
  File "/usr/lib/python3.6/site-packages/websocket/_handshake.py", line 122, in _get_resp_headers
    raise WebSocketBadStatusException("Handshake status %d", status)
websocket._exceptions.WebSocketBadStatusException: Handshake status 503


--------------------
2018-01-26 15:47:41 - Exception on message: {'type': 'partition', 'server_id': 'heim.1', 'server_era': '0363gb00e2dq8'}:
Traceback (most recent call last):
  File "heimdall.py", line 208, in <module>
    heimdall.disconnect()
  File "/home/struan/python/karelia/karelia.py", line 56, in connect
    "wss://euphoria.io/room/{}/ws".format(self.room))
  File "/usr/lib/python3.6/site-packages/websocket/_core.py", line 487, in create_connection
    websock.connect(url, **options)
  File "/usr/lib/python3.6/site-packages/websocket/_core.py", line 214, in connect
    self.handshake_response = handshake(self.sock, *addrs, **options)
  File "/usr/lib/python3.6/site-packages/websocket/_handshake.py", line 65, in handshake
    status, resp = _get_resp_headers(sock)
  File "/usr/lib/python3.6/site-packages/websocket/_handshake.py", line 122, in _get_resp_headers
    raise WebSocketBadStatusException("Handshake status %d", status)
websocket._exceptions.WebSocketBadStatusException: Handshake status 503


--------------------
2018-01-26 15:47:47 - Exception on message: {'type': 'partition', 'server_id': 'heim.1', 'server_era': '0363gb00e2dq8'}:
Traceback (most recent call last):
  File "heimdall.py", line 208, in <module>
    heimdall.disconnect()
  File "/home/struan/python/karelia/karelia.py", line 56, in connect
    "wss://euphoria.io/room/{}/ws".format(self.room))
  File "/usr/lib/python3.6/site-packages/websocket/_core.py", line 487, in create_connection
    websock.connect(url, **options)
  File "/usr/lib/python3.6/site-packages/websocket/_core.py", line 214, in connect
    self.handshake_response = handshake(self.sock, *addrs, **options)
  File "/usr/lib/python3.6/site-packages/websocket/_handshake.py", line 65, in handshake
    status, resp = _get_resp_headers(sock)
  File "/usr/lib/python3.6/site-packages/websocket/_handshake.py", line 122, in _get_resp_headers
    raise WebSocketBadStatusException("Handshake status %d", status)
websocket._exceptions.WebSocketBadStatusException: Handshake status 503


--------------------
2018-01-26 15:47:53 - Exception on message: {'type': 'partition', 'server_id': 'heim.1', 'server_era': '0363gb00e2dq8'}:
Traceback (most recent call last):
  File "heimdall.py", line 208, in <module>
    heimdall.disconnect()
  File "/home/struan/python/karelia/karelia.py", line 56, in connect
    "wss://euphoria.io/room/{}/ws".format(self.room))
  File "/usr/lib/python3.6/site-packages/websocket/_core.py", line 487, in create_connection
    websock.connect(url, **options)
  File "/usr/lib/python3.6/site-packages/websocket/_core.py", line 214, in connect
    self.handshake_response = handshake(self.sock, *addrs, **options)
  File "/usr/lib/python3.6/site-packages/websocket/_handshake.py", line 65, in handshake
    status, resp = _get_resp_headers(sock)
  File "/usr/lib/python3.6/site-packages/websocket/_handshake.py", line 122, in _get_resp_headers
    raise WebSocketBadStatusException("Handshake status %d", status)
websocket._exceptions.WebSocketBadStatusException: Handshake status 503


--------------------
2018-02-11 14:49:14 - Exception on message: {'id': '037xg4miievb4', 'parent': '037xdu8zyl2ww', 'time': 1518360554, 'sender': {'id': 'account:01ha19ib9296o', 'name': 'Pouncy Silverkitten', 'server_id': 'heim.1', 'server_era': '03769mpwsey2o', 'session_id': '746564632d686e72744d593d-3f9069df49b5bbe6'}, 'content': '!stats', 'edited': None, 'deleted': None}:
Traceback (most recent call last):
  File "heimdall.py", line 294, in <module>
    day = "{}-{}-{}".format(sentDay.year(), sentDay.month(), sentDay.day())
TypeError: 'int' object is not callable


--------------------
2018-02-11 14:51:42 - Exception on message: {'id': '037xgcijk9qtc', 'parent': '037xdu8zyl2ww', 'time': 1518360701, 'sender': {'id': 'account:01ha19ib9296o', 'name': 'Pouncy Silverkitten', 'server_id': 'heim.1', 'server_era': '03769mpwsey2o', 'session_id': '746564632d686e72744d593d-3f9069df49b5bbe6'}, 'content': '!stats', 'edited': None, 'deleted': None}:
Traceback (most recent call last):
  File "heimdall.py", line 319, in <module>
    statsOf, str(count), numberOfDays, firstMessageSent, earliest[0], lastMessageSent, int(count / numberOfDays), busiestDay[0], busiestDay[1], position, len(results)), message['data']['id'])
NameError: name 'position' is not defined


--------------------
2018-02-11 14:53:31 - Exception on message: {'id': '037xgidwlytq8', 'parent': '037xdu8zyl2ww', 'time': 1518360811, 'sender': {'id': 'account:01ha19ib9296o', 'name': 'Pouncy Silverkitten', 'server_id': 'heim.1', 'server_era': '03769mpwsey2o', 'session_id': '746564632d686e72744d593d-3f9069df49b5bbf1'}, 'content': '!stats', 'edited': None, 'deleted': None}:
Traceback (most recent call last):
  File "heimdall.py", line 294, in <module>
    day = "{}-{}-{}".format(sentDay.year, sentDay.month, sentDay.da)
AttributeError: 'datetime.datetime' object has no attribute 'da'


--------------------
2018-02-11 14:54:02 - Exception on message: {'id': '037xgk0dqe8e8', 'parent': '037xdu8zyl2ww', 'time': 1518360841, 'sender': {'id': 'account:01ha19ib9296o', 'name': 'Pouncy Silverkitten', 'server_id': 'heim.1', 'server_era': '03769mpwsey2o', 'session_id': '746564632d686e72744d593d-3f9069df49b5bbf1'}, 'content': '!stats', 'edited': None, 'deleted': None}:
Traceback (most recent call last):
  File "heimdall.py", line 319, in <module>
    statsOf, str(count), numberOfDays, firstMessageSent, earliest[0], lastMessageSent, int(count / numberOfDays), busiestDay[0], busiestDay[1], position, len(results)), message['data']['id'])
NameError: name 'position' is not defined


--------------------
2018-02-11 14:56:09 - Exception on message: {'id': '037xgquduedxc', 'parent': '037xdu8zyl2ww', 'time': 1518360969, 'sender': {'id': 'account:01ha19ib9296o', 'name': 'Pouncy Silverkitten', 'server_id': 'heim.1', 'server_era': '03769mpwsey2o', 'session_id': '746564632d686e72744d593d-3f9069df49b5bbf1'}, 'content': '!kill @Heimdall', 'edited': None, 'deleted': None}:
Traceback (most recent call last):
  File "heimdall.py", line 219, in <module>
    if message['type'] == 'send-event':
TypeError: string indices must be integers


